2025-06-24 16:58:57 - services.catering_rules_service - CRITICAL - üî• –ü–†–ò–ù–£–î–ò–¢–ï–õ–¨–ù–ê–Ø –ü–ï–†–ï–ó–ê–ì–†–£–ó–ö–ê CateringRulesService!
2025-06-24 16:58:57 - __main__ - INFO - ‚úÖ SuperAIAgent —É—Å–ø–µ—à–Ω–æ –∏–º–ø–æ—Ä—Ç–∏—Ä–æ–≤–∞–Ω!
2025-06-24 16:58:57 - __main__ - INFO - üìÅ –î–∏—Ä–µ–∫—Ç–æ—Ä–∏–∏ –ø—Ä–æ–µ–∫—Ç–∞ –ø—Ä–æ–≤–µ—Ä–µ–Ω—ã
2025-06-24 16:58:57 - __main__ - INFO - üìÅ –ü–∞–ø–∫–∞ menu_files: C:\Users\F12$\eventbot\menu_files
2025-06-24 16:58:57 - __main__ - INFO - üìÑ –ù–∞–π–¥–µ–Ω–æ txt —Ñ–∞–π–ª–æ–≤: 6
2025-06-24 16:58:57 - __main__ - INFO -   - –±–∞–Ω–∫–µ—Ç–Ω–æ–µ –º–µ–Ω—é.txt
2025-06-24 16:58:57 - __main__ - INFO -   - –µ–¥–µ–Ω–∏—á–Ω—ã–µ –ø–æ–∑–∏—Ü–∏–∏.txt
2025-06-24 16:58:57 - __main__ - INFO -   - –Ω–∞–±–æ—Ä—ã —Å–µ—Ç–æ–≤.txt
2025-06-24 16:58:57 - __main__ - INFO -   - –Ω–∞–ø–∏—Ç–∫–∏_–º–µ–Ω—é.txt
2025-06-24 16:58:57 - __main__ - INFO -   - –Ω–æ–≤—ã–µ –∞–≤—Ç–æ—Ä—Å–∫–∏–µ —Å–µ—Ç—ã.txt
2025-06-24 16:58:57 - __main__ - INFO -   - –æ–±—â–µ–µ –º–µ–Ω—é.txt
2025-06-24 16:58:57 - __main__ - INFO - üöÄ –ò–Ω–∏—Ü–∏–∞–ª–∏–∑–∞—Ü–∏—è EventBot...
2025-06-24 16:58:57 - __main__ - INFO - üîß –ò–Ω–∏—Ü–∏–∞–ª–∏–∑–∞—Ü–∏—è —Å–µ—Ä–≤–∏—Å–æ–≤ EventBot...
2025-06-24 16:58:57 - __main__ - INFO - üìÅ –ò–Ω–∏—Ü–∏–∞–ª–∏–∑–∞—Ü–∏—è MenuService —Å –ø–∞–ø–∫–æ–π: C:\Users\F12$\eventbot\menu_files
2025-06-24 16:58:57 - menu_service_table_format - INFO - üîç –ü–æ–∏—Å–∫ txt —Ñ–∞–π–ª–æ–≤ –≤ –ø–∞–ø–∫–µ: C:\Users\F12$\eventbot\menu_files
2025-06-24 16:58:57 - menu_service_table_format - INFO - üìÅ –ê–±—Å–æ–ª—é—Ç–Ω—ã–π –ø—É—Ç—å: C:\Users\F12$\eventbot\menu_files
2025-06-24 16:58:57 - menu_service_table_format - INFO - üìÇ –°–æ–¥–µ—Ä–∂–∏–º–æ–µ –ø–∞–ø–∫–∏ C:\Users\F12$\eventbot\menu_files:
2025-06-24 16:58:57 - menu_service_table_format - INFO -   - –±–∞–Ω–∫–µ—Ç–Ω–æ–µ –º–µ–Ω—é.txt (—Ñ–∞–π–ª)
2025-06-24 16:58:57 - menu_service_table_format - INFO -   - –µ–¥–µ–Ω–∏—á–Ω—ã–µ –ø–æ–∑–∏—Ü–∏–∏.txt (—Ñ–∞–π–ª)
2025-06-24 16:58:57 - menu_service_table_format - INFO -   - –Ω–∞–±–æ—Ä—ã —Å–µ—Ç–æ–≤.txt (—Ñ–∞–π–ª)
2025-06-24 16:58:57 - menu_service_table_format - INFO -   - –Ω–∞–ø–∏—Ç–∫–∏_–º–µ–Ω—é.txt (—Ñ–∞–π–ª)
2025-06-24 16:58:57 - menu_service_table_format - INFO -   - –Ω–æ–≤—ã–µ –∞–≤—Ç–æ—Ä—Å–∫–∏–µ —Å–µ—Ç—ã.txt (—Ñ–∞–π–ª)
2025-06-24 16:58:57 - menu_service_table_format - INFO -   - –æ–±—â–µ–µ –º–µ–Ω—é.txt (—Ñ–∞–π–ª)
2025-06-24 16:58:57 - menu_service_table_format - INFO - üìÅ –ù–∞–π–¥–µ–Ω–æ txt —Ñ–∞–π–ª–æ–≤: 6
2025-06-24 16:58:57 - menu_service_table_format - INFO -   - –±–∞–Ω–∫–µ—Ç–Ω–æ–µ –º–µ–Ω—é.txt
2025-06-24 16:58:57 - menu_service_table_format - INFO -   - –µ–¥–µ–Ω–∏—á–Ω—ã–µ –ø–æ–∑–∏—Ü–∏–∏.txt
2025-06-24 16:58:57 - menu_service_table_format - INFO -   - –Ω–∞–±–æ—Ä—ã —Å–µ—Ç–æ–≤.txt
2025-06-24 16:58:57 - menu_service_table_format - INFO -   - –Ω–∞–ø–∏—Ç–∫–∏_–º–µ–Ω—é.txt
2025-06-24 16:58:57 - menu_service_table_format - INFO -   - –Ω–æ–≤—ã–µ –∞–≤—Ç–æ—Ä—Å–∫–∏–µ —Å–µ—Ç—ã.txt
2025-06-24 16:58:57 - menu_service_table_format - INFO -   - –æ–±—â–µ–µ –º–µ–Ω—é.txt
2025-06-24 16:58:57 - menu_service_table_format - INFO - üìÑ –û–±—Ä–∞–±–∞—Ç—ã–≤–∞–µ–º —Ñ–∞–π–ª: –±–∞–Ω–∫–µ—Ç–Ω–æ–µ –º–µ–Ω—é.txt
2025-06-24 16:58:57 - menu_service_table_format - INFO - üìñ –ß–∏—Ç–∞–µ–º —Ñ–∞–π–ª: C:\Users\F12$\eventbot\menu_files\–±–∞–Ω–∫–µ—Ç–Ω–æ–µ –º–µ–Ω—é.txt
2025-06-24 16:58:57 - menu_service_table_format - INFO - üìÑ –í —Ñ–∞–π–ª–µ –±–∞–Ω–∫–µ—Ç–Ω–æ–µ –º–µ–Ω—é.txt —Å—Ç—Ä–æ–∫: 12
2025-06-24 16:58:57 - menu_service_table_format - INFO - üìÇ –ö–∞—Ç–µ–≥–æ—Ä–∏—è –¥–ª—è –±–∞–Ω–∫–µ—Ç–Ω–æ–µ –º–µ–Ω—é.txt: –ë–∞–Ω–∫–µ—Ç–Ω—ã–µ –±–ª—é–¥–∞
2025-06-24 16:58:57 - menu_service_table_format - INFO - üîç –ü–∞—Ä—Å–∏–Ω–≥ —Ñ–∞–π–ª–∞ –±–∞–Ω–∫–µ—Ç–Ω–æ–µ –º–µ–Ω—é.txt, —Å—Ç—Ä–æ–∫: 12
2025-06-24 16:58:57 - menu_service_table_format - INFO - üìã –ó–∞–≥–æ–ª–æ–≤–æ–∫ —Ñ–∞–π–ª–∞ –±–∞–Ω–∫–µ—Ç–Ω–æ–µ –º–µ–Ω—é.txt: –ê—Ä—Ç–∏–∫—É–ª	–ù–∞–∏–º–µ–Ω–æ–≤–∞–Ω–∏–µ	–û–ø–∏—Å–∞–Ω–∏–µ	–í–µ—Å (–≥)	–¶–µ–Ω–∞ (‚ÇΩ)
2025-06-24 16:58:57 - menu_service_table_format - INFO - ‚úÖ –û–±–Ω–∞—Ä—É–∂–µ–Ω —Ç–∞–±–ª–∏—á–Ω—ã–π —Ñ–æ—Ä–º–∞—Ç –≤ –±–∞–Ω–∫–µ—Ç–Ω–æ–µ –º–µ–Ω—é.txt
2025-06-24 16:58:57 - menu_service_table_format - INFO - üìÑ –°—Ç—Ä–æ–∫ –¥–∞–Ω–Ω—ã—Ö –¥–ª—è –æ–±—Ä–∞–±–æ—Ç–∫–∏: 11
2025-06-24 16:58:57 - menu_service_table_format - INFO - ‚úÖ –ò–∑ –±–∞–Ω–∫–µ—Ç–Ω–æ–µ –º–µ–Ω—é.txt —É—Å–ø–µ—à–Ω–æ –æ–±—Ä–∞–±–æ—Ç–∞–Ω–æ 11 –∏–∑ 11 —Å—Ç—Ä–æ–∫
2025-06-24 16:58:57 - menu_service_table_format - INFO - ‚úÖ –ò–∑ —Ñ–∞–π–ª–∞ –±–∞–Ω–∫–µ—Ç–Ω–æ–µ –º–µ–Ω—é.txt –∏–∑–≤–ª–µ—á–µ–Ω–æ 11 –ø–æ–∑–∏—Ü–∏–π
2025-06-24 16:58:57 - menu_service_table_format - INFO -    - B001: –ì–æ–≤—è–∂–∏–π –±–æ–∫ –Ω–∞ –ø–æ–¥—É—à–∫–µ –∏–∑ –∫–∞—Ä—Ç–æ—Ñ–µ–ª—å–Ω–æ-—Ç—ã–∫–≤–µ–Ω–Ω–æ–≥–æ –ø—é—Ä–µ (1150‚ÇΩ)
2025-06-24 16:58:57 - menu_service_table_format - INFO -    - B002: –ó–∞–ø–µ—á–µ–Ω–Ω–∞—è —Å–∫—É–º–±—Ä–∏—è —Å –±–∞–∫–ª–∞–∂–∞–Ω–∞–º–∏ –∏ –∫—É–Ω–∂—É—Ç–Ω—ã–º —Å–æ—É—Å–æ–º (1100‚ÇΩ)
2025-06-24 16:58:57 - menu_service_table_format - INFO -    - B003: –ú–µ–¥–∞–ª—å–æ–Ω—ã –∏–∑ –≥–æ–≤—è–¥–∏–Ω—ã —Å —Å–µ–∑–æ–Ω–Ω—ã–º–∏ –≥—Ä–∏–±–∞–º–∏ (1350‚ÇΩ)
2025-06-24 16:58:57 - menu_service_table_format - INFO - üìÑ –±–∞–Ω–∫–µ—Ç–Ω–æ–µ –º–µ–Ω—é.txt: –∑–∞–≥—Ä—É–∂–µ–Ω–æ 11 –ø–æ–∑–∏—Ü–∏–π
2025-06-24 16:58:57 - menu_service_table_format - INFO - üìÑ –û–±—Ä–∞–±–∞—Ç—ã–≤–∞–µ–º —Ñ–∞–π–ª: –µ–¥–µ–Ω–∏—á–Ω—ã–µ –ø–æ–∑–∏—Ü–∏–∏.txt
2025-06-24 16:58:57 - menu_service_table_format - INFO - üìñ –ß–∏—Ç–∞–µ–º —Ñ–∞–π–ª: C:\Users\F12$\eventbot\menu_files\–µ–¥–µ–Ω–∏—á–Ω—ã–µ –ø–æ–∑–∏—Ü–∏–∏.txt
2025-06-24 16:58:57 - menu_service_table_format - INFO - üìÑ –í —Ñ–∞–π–ª–µ –µ–¥–µ–Ω–∏—á–Ω—ã–µ –ø–æ–∑–∏—Ü–∏–∏.txt —Å—Ç—Ä–æ–∫: 43
2025-06-24 16:58:57 - menu_service_table_format - INFO - üìÇ –ö–∞—Ç–µ–≥–æ—Ä–∏—è –¥–ª—è –µ–¥–µ–Ω–∏—á–Ω—ã–µ –ø–æ–∑–∏—Ü–∏–∏.txt: –ï–¥–µ–Ω–∏—á–Ω—ã–µ –ü–æ–∑–∏—Ü–∏–∏
2025-06-24 16:58:57 - menu_service_table_format - INFO - üîç –ü–∞—Ä—Å–∏–Ω–≥ —Ñ–∞–π–ª–∞ –µ–¥–µ–Ω–∏—á–Ω—ã–µ –ø–æ–∑–∏—Ü–∏–∏.txt, —Å—Ç—Ä–æ–∫: 43
2025-06-24 16:58:57 - menu_service_table_format - INFO - üìã –ó–∞–≥–æ–ª–æ–≤–æ–∫ —Ñ–∞–π–ª–∞ –µ–¥–µ–Ω–∏—á–Ω—ã–µ –ø–æ–∑–∏—Ü–∏–∏.txt: –ê—Ä—Ç–∏–∫—É–ª	–ù–∞–∏–º–µ–Ω–æ–≤–∞–Ω–∏–µ	–û–ø–∏—Å–∞–Ω–∏–µ	–í–µ—Å (–≥)	–¶–µ–Ω–∞ (‚ÇΩ)
2025-06-24 16:58:57 - menu_service_table_format - INFO - ‚úÖ –û–±–Ω–∞—Ä—É–∂–µ–Ω —Ç–∞–±–ª–∏—á–Ω—ã–π —Ñ–æ—Ä–º–∞—Ç –≤ –µ–¥–µ–Ω–∏—á–Ω—ã–µ –ø–æ–∑–∏—Ü–∏–∏.txt
2025-06-24 16:58:57 - menu_service_table_format - INFO - üìÑ –°—Ç—Ä–æ–∫ –¥–∞–Ω–Ω—ã—Ö –¥–ª—è –æ–±—Ä–∞–±–æ—Ç–∫–∏: 42
2025-06-24 16:58:57 - menu_service_table_format - INFO - ‚úÖ –ò–∑ –µ–¥–µ–Ω–∏—á–Ω—ã–µ –ø–æ–∑–∏—Ü–∏–∏.txt —É—Å–ø–µ—à–Ω–æ –æ–±—Ä–∞–±–æ—Ç–∞–Ω–æ 42 –∏–∑ 42 —Å—Ç—Ä–æ–∫
2025-06-24 16:58:57 - menu_service_table_format - INFO - ‚úÖ –ò–∑ —Ñ–∞–π–ª–∞ –µ–¥–µ–Ω–∏—á–Ω—ã–µ –ø–æ–∑–∏—Ü–∏–∏.txt –∏–∑–≤–ª–µ—á–µ–Ω–æ 42 –ø–æ–∑–∏—Ü–∏–π
2025-06-24 16:58:57 - menu_service_table_format - INFO -    - IK001: –ê–Ω—Ç–∏–ø–∞—Å—Ç–∏ —Å —á–µ—Ä—Ä–∏, –¥–∞–π–∫–æ–Ω–æ–º –∏ –æ–ª–∏–≤–∫–æ–π –Ω–∞ –±–æ—Ä–æ–¥–∏–Ω—Å–∫–æ–º —Ç–æ—Å—Ç–µ (90‚ÇΩ)
2025-06-24 16:58:57 - menu_service_table_format - INFO -    - IK002: –î—É—ç—Ç –∏–∑ —Ç—É–Ω—Ü–∞ –∏ –º—É—Ä–º–∞–Ω—Å–∫–æ–≥–æ –ª–æ—Å–æ—Å—è (350‚ÇΩ)
2025-06-24 16:58:57 - menu_service_table_format - INFO -    - IK003: –ö–æ—Ä–æ–ª–µ–≤—Å–∫–∏–π —Ñ–∏–Ω–∏–∫ —Å —Ä–∏–∫–æ—Ç—Ç–æ–π –∏ —Ñ–∏—Å—Ç–∞—à–∫–æ–π (125‚ÇΩ)
2025-06-24 16:58:57 - menu_service_table_format - INFO - üìÑ –µ–¥–µ–Ω–∏—á–Ω—ã–µ –ø–æ–∑–∏—Ü–∏–∏.txt: –∑–∞–≥—Ä—É–∂–µ–Ω–æ 42 –ø–æ–∑–∏—Ü–∏–π
2025-06-24 16:58:57 - menu_service_table_format - INFO - üìÑ –û–±—Ä–∞–±–∞—Ç—ã–≤–∞–µ–º —Ñ–∞–π–ª: –Ω–∞–±–æ—Ä—ã —Å–µ—Ç–æ–≤.txt
2025-06-24 16:58:57 - menu_service_table_format - INFO - üìñ –ß–∏—Ç–∞–µ–º —Ñ–∞–π–ª: C:\Users\F12$\eventbot\menu_files\–Ω–∞–±–æ—Ä—ã —Å–µ—Ç–æ–≤.txt
2025-06-24 16:58:57 - menu_service_table_format - INFO - üìÑ –í —Ñ–∞–π–ª–µ –Ω–∞–±–æ—Ä—ã —Å–µ—Ç–æ–≤.txt —Å—Ç—Ä–æ–∫: 22
2025-06-24 16:58:57 - menu_service_table_format - INFO - üìÇ –ö–∞—Ç–µ–≥–æ—Ä–∏—è –¥–ª—è –Ω–∞–±–æ—Ä—ã —Å–µ—Ç–æ–≤.txt: –ì–æ—Ç–æ–≤—ã–µ —Å–µ—Ç—ã
2025-06-24 16:58:57 - menu_service_table_format - INFO - üîç –ü–∞—Ä—Å–∏–Ω–≥ —Ñ–∞–π–ª–∞ –Ω–∞–±–æ—Ä—ã —Å–µ—Ç–æ–≤.txt, —Å—Ç—Ä–æ–∫: 22
2025-06-24 16:58:57 - menu_service_table_format - INFO - üìã –ó–∞–≥–æ–ª–æ–≤–æ–∫ —Ñ–∞–π–ª–∞ –Ω–∞–±–æ—Ä—ã —Å–µ—Ç–æ–≤.txt: –ê—Ä—Ç–∏–∫—É–ª	–ù–∞–∏–º–µ–Ω–æ–≤–∞–Ω–∏–µ	–û–ø–∏—Å–∞–Ω–∏–µ	–í–µ—Å (–≥)	–¶–µ–Ω–∞ (‚ÇΩ)
2025-06-24 16:58:57 - menu_service_table_format - INFO - ‚úÖ –û–±–Ω–∞—Ä—É–∂–µ–Ω —Ç–∞–±–ª–∏—á–Ω—ã–π —Ñ–æ—Ä–º–∞—Ç –≤ –Ω–∞–±–æ—Ä—ã —Å–µ—Ç–æ–≤.txt
2025-06-24 16:58:57 - menu_service_table_format - INFO - üìÑ –°—Ç—Ä–æ–∫ –¥–∞–Ω–Ω—ã—Ö –¥–ª—è –æ–±—Ä–∞–±–æ—Ç–∫–∏: 21
2025-06-24 16:58:57 - menu_service_table_format - INFO - ‚úÖ –ò–∑ –Ω–∞–±–æ—Ä—ã —Å–µ—Ç–æ–≤.txt —É—Å–ø–µ—à–Ω–æ –æ–±—Ä–∞–±–æ—Ç–∞–Ω–æ 21 –∏–∑ 21 —Å—Ç—Ä–æ–∫
2025-06-24 16:58:57 - menu_service_table_format - INFO - ‚úÖ –ò–∑ —Ñ–∞–π–ª–∞ –Ω–∞–±–æ—Ä—ã —Å–µ—Ç–æ–≤.txt –∏–∑–≤–ª–µ—á–µ–Ω–æ 21 –ø–æ–∑–∏—Ü–∏–π
2025-06-24 16:58:57 - menu_service_table_format - INFO -    - S001: –ö–æ—Ñ–µ-–ë—Ä–µ–π–∫ –Ω–∞ 25-30 —á–µ–ª–æ–≤–µ–∫ (22290‚ÇΩ)
2025-06-24 16:58:57 - menu_service_table_format - INFO -    - S002: –í–µ—á–µ—Ä –≤ –ò—Ç–∞–ª–∏–∏ –Ω–∞ 5-10 —á–µ–ª–æ–≤–µ–∫ (14990‚ÇΩ)
2025-06-24 16:58:57 - menu_service_table_format - INFO -    - S003: –£–∏–∫-—ç–Ω–¥ –≤ –ò—Ç–∞–ª–∏–∏ –Ω–∞ 15-20 —á–µ–ª–æ–≤–µ–∫ (49390‚ÇΩ)
2025-06-24 16:58:57 - menu_service_table_format - INFO - üìÑ –Ω–∞–±–æ—Ä—ã —Å–µ—Ç–æ–≤.txt: –∑–∞–≥—Ä—É–∂–µ–Ω–æ 21 –ø–æ–∑–∏—Ü–∏–π
2025-06-24 16:58:57 - menu_service_table_format - INFO - üìÑ –û–±—Ä–∞–±–∞—Ç—ã–≤–∞–µ–º —Ñ–∞–π–ª: –Ω–∞–ø–∏—Ç–∫–∏_–º–µ–Ω—é.txt
2025-06-24 16:58:57 - menu_service_table_format - INFO - üìñ –ß–∏—Ç–∞–µ–º —Ñ–∞–π–ª: C:\Users\F12$\eventbot\menu_files\–Ω–∞–ø–∏—Ç–∫–∏_–º–µ–Ω—é.txt
2025-06-24 16:58:57 - menu_service_table_format - INFO - üìÑ –í —Ñ–∞–π–ª–µ –Ω–∞–ø–∏—Ç–∫–∏_–º–µ–Ω—é.txt —Å—Ç—Ä–æ–∫: 16
2025-06-24 16:58:57 - menu_service_table_format - INFO - üìÇ –ö–∞—Ç–µ–≥–æ—Ä–∏—è –¥–ª—è –Ω–∞–ø–∏—Ç–∫–∏_–º–µ–Ω—é.txt: –ù–∞–ø–∏—Ç–∫–∏
2025-06-24 16:58:57 - menu_service_table_format - INFO - üîç –ü–∞—Ä—Å–∏–Ω–≥ —Ñ–∞–π–ª–∞ –Ω–∞–ø–∏—Ç–∫–∏_–º–µ–Ω—é.txt, —Å—Ç—Ä–æ–∫: 16
2025-06-24 16:58:57 - menu_service_table_format - INFO - üìã –ó–∞–≥–æ–ª–æ–≤–æ–∫ —Ñ–∞–π–ª–∞ –Ω–∞–ø–∏—Ç–∫–∏_–º–µ–Ω—é.txt: –ê—Ä—Ç–∏–∫—É–ª	–ù–∞–∏–º–µ–Ω–æ–≤–∞–Ω–∏–µ	–û–ø–∏—Å–∞–Ω–∏–µ	–í–µ—Å (–º–ª)	–¶–µ–Ω–∞ (‚ÇΩ)
2025-06-24 16:58:57 - menu_service_table_format - INFO - ‚úÖ –û–±–Ω–∞—Ä—É–∂–µ–Ω —Ç–∞–±–ª–∏—á–Ω—ã–π —Ñ–æ—Ä–º–∞—Ç –≤ –Ω–∞–ø–∏—Ç–∫–∏_–º–µ–Ω—é.txt
2025-06-24 16:58:57 - menu_service_table_format - INFO - üìÑ –°—Ç—Ä–æ–∫ –¥–∞–Ω–Ω—ã—Ö –¥–ª—è –æ–±—Ä–∞–±–æ—Ç–∫–∏: 15
2025-06-24 16:58:57 - menu_service_table_format - INFO - ‚úÖ –ò–∑ –Ω–∞–ø–∏—Ç–∫–∏_–º–µ–Ω—é.txt —É—Å–ø–µ—à–Ω–æ –æ–±—Ä–∞–±–æ—Ç–∞–Ω–æ 15 –∏–∑ 15 —Å—Ç—Ä–æ–∫
2025-06-24 16:58:57 - menu_service_table_format - INFO - ‚úÖ –ò–∑ —Ñ–∞–π–ª–∞ –Ω–∞–ø–∏—Ç–∫–∏_–º–µ–Ω—é.txt –∏–∑–≤–ª–µ—á–µ–Ω–æ 15 –ø–æ–∑–∏—Ü–∏–π
2025-06-24 16:58:57 - menu_service_table_format - INFO -    - N001: –ö–æ—Ñ–µ —ç—Å–ø—Ä–µ—Å—Å–æ (80‚ÇΩ)
2025-06-24 16:58:57 - menu_service_table_format - INFO -    - N002: –ö–æ—Ñ–µ –∞–º–µ—Ä–∏–∫–∞–Ω–æ (100‚ÇΩ)
2025-06-24 16:58:57 - menu_service_table_format - INFO -    - N003: –ö–æ—Ñ–µ –∫–∞–ø—É—á–∏–Ω–æ (120‚ÇΩ)
2025-06-24 16:58:57 - menu_service_table_format - INFO - üìÑ –Ω–∞–ø–∏—Ç–∫–∏_–º–µ–Ω—é.txt: –∑–∞–≥—Ä—É–∂–µ–Ω–æ 15 –ø–æ–∑–∏—Ü–∏–π
2025-06-24 16:58:57 - menu_service_table_format - INFO - üìÑ –û–±—Ä–∞–±–∞—Ç—ã–≤–∞–µ–º —Ñ–∞–π–ª: –Ω–æ–≤—ã–µ –∞–≤—Ç–æ—Ä—Å–∫–∏–µ —Å–µ—Ç—ã.txt
2025-06-24 16:58:57 - menu_service_table_format - INFO - üìñ –ß–∏—Ç–∞–µ–º —Ñ–∞–π–ª: C:\Users\F12$\eventbot\menu_files\–Ω–æ–≤—ã–µ –∞–≤—Ç–æ—Ä—Å–∫–∏–µ —Å–µ—Ç—ã.txt
2025-06-24 16:58:57 - menu_service_table_format - INFO - üìÑ –í —Ñ–∞–π–ª–µ –Ω–æ–≤—ã–µ –∞–≤—Ç–æ—Ä—Å–∫–∏–µ —Å–µ—Ç—ã.txt —Å—Ç—Ä–æ–∫: 12
2025-06-24 16:58:57 - menu_service_table_format - INFO - üìÇ –ö–∞—Ç–µ–≥–æ—Ä–∏—è –¥–ª—è –Ω–æ–≤—ã–µ –∞–≤—Ç–æ—Ä—Å–∫–∏–µ —Å–µ—Ç—ã.txt: –ì–æ—Ç–æ–≤—ã–µ —Å–µ—Ç—ã
2025-06-24 16:58:57 - menu_service_table_format - INFO - üîç –ü–∞—Ä—Å–∏–Ω–≥ —Ñ–∞–π–ª–∞ –Ω–æ–≤—ã–µ –∞–≤—Ç–æ—Ä—Å–∫–∏–µ —Å–µ—Ç—ã.txt, —Å—Ç—Ä–æ–∫: 12
2025-06-24 16:58:57 - menu_service_table_format - INFO - üìã –ó–∞–≥–æ–ª–æ–≤–æ–∫ —Ñ–∞–π–ª–∞ –Ω–æ–≤—ã–µ –∞–≤—Ç–æ—Ä—Å–∫–∏–µ —Å–µ—Ç—ã.txt: –ê—Ä—Ç–∏–∫—É–ª	–ù–∞–∏–º–µ–Ω–æ–≤–∞–Ω–∏–µ	–û–ø–∏—Å–∞–Ω–∏–µ	–í–µ—Å (–≥)	–¶–µ–Ω–∞ (‚ÇΩ)
2025-06-24 16:58:57 - menu_service_table_format - INFO - ‚úÖ –û–±–Ω–∞—Ä—É–∂–µ–Ω —Ç–∞–±–ª–∏—á–Ω—ã–π —Ñ–æ—Ä–º–∞—Ç –≤ –Ω–æ–≤—ã–µ –∞–≤—Ç–æ—Ä—Å–∫–∏–µ —Å–µ—Ç—ã.txt
2025-06-24 16:58:57 - menu_service_table_format - INFO - üìÑ –°—Ç—Ä–æ–∫ –¥–∞–Ω–Ω—ã—Ö –¥–ª—è –æ–±—Ä–∞–±–æ—Ç–∫–∏: 11
2025-06-24 16:58:57 - menu_service_table_format - INFO - ‚úÖ –ò–∑ –Ω–æ–≤—ã–µ –∞–≤—Ç–æ—Ä—Å–∫–∏–µ —Å–µ—Ç—ã.txt —É—Å–ø–µ—à–Ω–æ –æ–±—Ä–∞–±–æ—Ç–∞–Ω–æ 11 –∏–∑ 11 —Å—Ç—Ä–æ–∫
2025-06-24 16:58:57 - menu_service_table_format - INFO - ‚úÖ –ò–∑ —Ñ–∞–π–ª–∞ –Ω–æ–≤—ã–µ –∞–≤—Ç–æ—Ä—Å–∫–∏–µ —Å–µ—Ç—ã.txt –∏–∑–≤–ª–µ—á–µ–Ω–æ 11 –ø–æ–∑–∏—Ü–∏–π
2025-06-24 16:58:57 - menu_service_table_format - INFO -    - AS001: –°–µ—Ç –î–µ–ª–æ–≤–æ–π –Ω–∞ 21-25 –ø–µ—Ä—Å–æ–Ω (25990‚ÇΩ)
2025-06-24 16:58:57 - menu_service_table_format - INFO -    - AS002: –°–µ—Ç –ü—Ä–∞–∑–¥–Ω–∏—á–Ω—ã–π –Ω–∞ 21-25 –ø–µ—Ä—Å–æ–Ω (28590‚ÇΩ)
2025-06-24 16:58:57 - menu_service_table_format - INFO -    - AS003: –°–µ—Ç –ü—Ä–∞–∑–¥–Ω–∏—á–Ω—ã–π –Ω–∞ 10-15 –ø–µ—Ä—Å–æ–Ω (17990‚ÇΩ)
2025-06-24 16:58:57 - menu_service_table_format - INFO - üìÑ –Ω–æ–≤—ã–µ –∞–≤—Ç–æ—Ä—Å–∫–∏–µ —Å–µ—Ç—ã.txt: –∑–∞–≥—Ä—É–∂–µ–Ω–æ 11 –ø–æ–∑–∏—Ü–∏–π
2025-06-24 16:58:57 - menu_service_table_format - INFO - üìÑ –û–±—Ä–∞–±–∞—Ç—ã–≤–∞–µ–º —Ñ–∞–π–ª: –æ–±—â–µ–µ –º–µ–Ω—é.txt
2025-06-24 16:58:57 - menu_service_table_format - INFO - üìñ –ß–∏—Ç–∞–µ–º —Ñ–∞–π–ª: C:\Users\F12$\eventbot\menu_files\–æ–±—â–µ–µ –º–µ–Ω—é.txt
2025-06-24 16:58:57 - menu_service_table_format - INFO - üìÑ –í —Ñ–∞–π–ª–µ –æ–±—â–µ–µ –º–µ–Ω—é.txt —Å—Ç—Ä–æ–∫: 43
2025-06-24 16:58:57 - menu_service_table_format - INFO - üìÇ –ö–∞—Ç–µ–≥–æ—Ä–∏—è –¥–ª—è –æ–±—â–µ–µ –º–µ–Ω—é.txt: –û—Å–Ω–æ–≤–Ω–æ–µ –º–µ–Ω—é
2025-06-24 16:58:57 - menu_service_table_format - INFO - üîç –ü–∞—Ä—Å–∏–Ω–≥ —Ñ–∞–π–ª–∞ –æ–±—â–µ–µ –º–µ–Ω—é.txt, —Å—Ç—Ä–æ–∫: 43
2025-06-24 16:58:57 - menu_service_table_format - INFO - üìã –ó–∞–≥–æ–ª–æ–≤–æ–∫ —Ñ–∞–π–ª–∞ –æ–±—â–µ–µ –º–µ–Ω—é.txt: –ê—Ä—Ç–∏–∫—É–ª	–ù–∞–∏–º–µ–Ω–æ–≤–∞–Ω–∏–µ	–û–ø–∏—Å–∞–Ω–∏–µ	–í–µ—Å (–≥)	–¶–µ–Ω–∞ (‚ÇΩ)
2025-06-24 16:58:57 - menu_service_table_format - INFO - ‚úÖ –û–±–Ω–∞—Ä—É–∂–µ–Ω —Ç–∞–±–ª–∏—á–Ω—ã–π —Ñ–æ—Ä–º–∞—Ç –≤ –æ–±—â–µ–µ –º–µ–Ω—é.txt
2025-06-24 16:58:57 - menu_service_table_format - INFO - üìÑ –°—Ç—Ä–æ–∫ –¥–∞–Ω–Ω—ã—Ö –¥–ª—è –æ–±—Ä–∞–±–æ—Ç–∫–∏: 42
2025-06-24 16:58:57 - menu_service_table_format - INFO - ‚úÖ –ò–∑ –æ–±—â–µ–µ –º–µ–Ω—é.txt —É—Å–ø–µ—à–Ω–æ –æ–±—Ä–∞–±–æ—Ç–∞–Ω–æ 42 –∏–∑ 42 —Å—Ç—Ä–æ–∫
2025-06-24 16:58:57 - menu_service_table_format - INFO - ‚úÖ –ò–∑ —Ñ–∞–π–ª–∞ –æ–±—â–µ–µ –º–µ–Ω—é.txt –∏–∑–≤–ª–µ—á–µ–Ω–æ 42 –ø–æ–∑–∏—Ü–∏–π
2025-06-24 16:58:57 - menu_service_table_format - INFO -    - K001: –°–µ—Ç –í–µ–≥–µ—Ç–∞—Ä–∏–∞–Ω—Å–∫–∏–π (4590‚ÇΩ)
2025-06-24 16:58:57 - menu_service_table_format - INFO -    - K002: –°–µ—Ç –≤–µ–≥–µ—Ç–∞—Ä–∏–∞–Ω—Å–∫–∏—Ö –∫–∞–Ω–∞–ø–µ Veggie (2990‚ÇΩ)
2025-06-24 16:58:57 - menu_service_table_format - INFO -    - K003: –°–µ—Ç –≤–µ–≥–µ—Ç–∞—Ä–∏–∞–Ω—Å–∫–∏—Ö –∫–∞–Ω–∞–ø–µ Antipasti (2490‚ÇΩ)
2025-06-24 16:58:57 - menu_service_table_format - INFO - üìÑ –æ–±—â–µ–µ –º–µ–Ω—é.txt: –∑–∞–≥—Ä—É–∂–µ–Ω–æ 42 –ø–æ–∑–∏—Ü–∏–π
2025-06-24 16:58:57 - menu_service_table_format - INFO - üìÇ –°–æ–∑–¥–∞–Ω–Ω—ã–µ –∫–∞—Ç–µ–≥–æ—Ä–∏–∏:
2025-06-24 16:58:57 - menu_service_table_format - INFO -   - –ë–∞–Ω–∫–µ—Ç–Ω—ã–µ –±–ª—é–¥–∞: 11 –ø–æ–∑–∏—Ü–∏–π
2025-06-24 16:58:57 - menu_service_table_format - INFO -   - –ï–¥–µ–Ω–∏—á–Ω—ã–µ –ü–æ–∑–∏—Ü–∏–∏: 42 –ø–æ–∑–∏—Ü–∏–π
2025-06-24 16:58:57 - menu_service_table_format - INFO -   - –ì–æ—Ç–æ–≤—ã–µ —Å–µ—Ç—ã: 32 –ø–æ–∑–∏—Ü–∏–π
2025-06-24 16:58:57 - menu_service_table_format - INFO -   - –ù–∞–ø–∏—Ç–∫–∏: 15 –ø–æ–∑–∏—Ü–∏–π
2025-06-24 16:58:57 - menu_service_table_format - INFO -   - –û—Å–Ω–æ–≤–Ω–æ–µ –º–µ–Ω—é: 42 –ø–æ–∑–∏—Ü–∏–π
2025-06-24 16:58:57 - menu_service_table_format - INFO - ‚úÖ –í—Å–µ–≥–æ –∑–∞–≥—Ä—É–∂–µ–Ω–æ 142 –ø–æ–∑–∏—Ü–∏–π –∏–∑ 6 —Ñ–∞–π–ª–æ–≤
2025-06-24 16:58:57 - services.claude_api_service - INFO - Enhanced Claude API Service v2.0 –∏–Ω–∏—Ü–∏–∞–ª–∏–∑–∏—Ä–æ–≤–∞–Ω
2025-06-24 16:58:57 - services.claude_api_service - ERROR - –û—à–∏–±–∫–∞ –∑–∞–≥—Ä—É–∑–∫–∏ –º–µ–Ω—é: No module named 'menu_service'
2025-06-24 16:58:57 - __main__ - INFO - ‚úÖ Claude API –∏–Ω–∏—Ü–∏–∞–ª–∏–∑–∏—Ä–æ–≤–∞–Ω
2025-06-24 16:58:58 - services.excel_estimate_generator - INFO - Excel –≥–µ–Ω–µ—Ä–∞—Ç–æ—Ä –≥–æ—Ç–æ–≤
2025-06-24 16:58:58 - services.catering_rules_service - CRITICAL - üîß –°–û–ó–î–ê–ï–¢–°–Ø –ù–û–í–´–ô CateringRulesService v2.1!
2025-06-24 16:58:58 - services.catering_rules_service - CRITICAL - ‚úÖ –ò–°–ü–†–ê–í–õ–ï–ù–ù–´–ï –°–¢–ê–ù–î–ê–†–¢–´ –ó–ê–ì–†–£–ñ–ï–ù–´!
2025-06-24 16:58:58 - services.client_database - INFO - –ë–∞–∑–∞ –¥–∞–Ω–Ω—ã—Ö –∑–∞–≥—Ä—É–∂–µ–Ω–∞
2025-06-24 16:58:58 - __main__ - INFO - ü§ñ –ò–Ω–∏—Ü–∏–∞–ª–∏–∑–∞—Ü–∏—è –ò–ò-–ø–æ–º–æ—â–Ω–∏–∫–æ–≤...
2025-06-24 16:58:58 - services.intelligent_manager_assistant - INFO - ‚úÖ IntelligentAssistant –∏–Ω–∏—Ü–∏–∞–ª–∏–∑–∏—Ä–æ–≤–∞–Ω
2025-06-24 16:58:58 - services.intelligent_manager_assistant - INFO - ‚úÖ IntelligentAssistant —Å–æ–∑–¥–∞–Ω —É—Å–ø–µ—à–Ω–æ
2025-06-24 16:58:58 - __main__ - INFO - ‚úÖ Intelligent Assistant —Å–æ–∑–¥–∞–Ω
2025-06-24 16:58:58 - services.intelligent_manager_assistant - INFO - üéâ SuperAIAgent –∏–Ω–∏—Ü–∏–∞–ª–∏–∑–∏—Ä–æ–≤–∞–Ω!
2025-06-24 16:58:58 - services.intelligent_manager_assistant - INFO - üéâ SuperAIAgent —Å–æ–∑–¥–∞–Ω —É—Å–ø–µ—à–Ω–æ
2025-06-24 16:58:58 - __main__ - INFO - üéâ –°–£–ü–ï–† –ò–ò-–ê–ì–ï–ù–¢ –ê–ö–¢–ò–í–ò–†–û–í–ê–ù!
2025-06-24 16:58:58 - __main__ - INFO - ‚úÖ –í—Å–µ —Å–µ—Ä–≤–∏—Å—ã –∏–Ω–∏—Ü–∏–∞–ª–∏–∑–∏—Ä–æ–≤–∞–Ω—ã
2025-06-24 16:58:58 - __main__ - INFO - ============================================================
2025-06-24 16:58:58 - __main__ - INFO - ü§ñ EventBot AI v2.1 - –¢–ê–ë–õ–ò–ß–ù–´–ô –§–û–†–ú–ê–¢ TXT
2025-06-24 16:58:58 - __main__ - INFO - ============================================================
2025-06-24 16:58:58 - __main__ - INFO - üìÅ –ü–∞–ø–∫–∞ –º–µ–Ω—é: C:\Users\F12$\eventbot\menu_files
2025-06-24 16:58:58 - __main__ - INFO - üìÑ TXT —Ñ–∞–π–ª–æ–≤: 6
2025-06-24 16:58:58 - __main__ - INFO - üìä –ü–æ–∑–∏—Ü–∏–π –º–µ–Ω—é: 142
2025-06-24 16:58:58 - __main__ - INFO - üìÇ –ö–∞—Ç–µ–≥–æ—Ä–∏–π: 5
2025-06-24 16:58:58 - __main__ - INFO - üìã –§–æ—Ä–º–∞—Ç: –ê—Ä—Ç–∏–∫—É–ª‚Üí–ù–∞–∑–≤–∞–Ω–∏–µ‚Üí–û–ø–∏—Å–∞–Ω–∏–µ‚Üí–í–µ—Å‚Üí–¶–µ–Ω–∞
2025-06-24 16:58:58 - __main__ - INFO - üë• –ú–µ–Ω–µ–¥–∂–µ—Ä–æ–≤: 1
2025-06-24 16:58:58 - __main__ - INFO - ü§ñ Claude AI: ‚úÖ –ê–∫—Ç–∏–≤–µ–Ω
2025-06-24 16:58:58 - __main__ - INFO - üß† SuperAI: ‚úÖ –ê–∫—Ç–∏–≤–µ–Ω
2025-06-24 16:58:58 - __main__ - INFO - üìä Excel: ‚úÖ –ì–æ—Ç–æ–≤
2025-06-24 16:58:58 - __main__ - INFO - üßÆ –ö–∞–ª—å–∫—É–ª—è—Ç–æ—Ä: ‚úÖ –ò—Å–ø—Ä–∞–≤–ª–µ–Ω–Ω—ã–µ —Ä–∞—Å—á–µ—Ç—ã
2025-06-24 16:58:58 - __main__ - INFO - üöÄ –†–µ–∂–∏–º: ‚ö° Production
2025-06-24 16:58:58 - __main__ - INFO - ============================================================
2025-06-24 16:58:59 - __main__ - INFO - ‚úÖ –û–±—Ä–∞–±–æ—Ç—á–∏–∫–∏ –∫–æ–º–∞–Ω–¥ –Ω–∞—Å—Ç—Ä–æ–µ–Ω—ã
2025-06-24 16:58:59 - __main__ - INFO - üöÄ EventBot AI v2.1 –∑–∞–ø—É—Å–∫–∞–µ—Ç—Å—è...
2025-06-24 16:58:59 - __main__ - INFO - üìÅ –ú–µ–Ω—é –∏–∑: C:\Users\F12$\eventbot\menu_files
2025-06-24 16:58:59 - __main__ - INFO - üß† SuperAI: ‚úÖ –ê–∫—Ç–∏–≤–µ–Ω
2025-06-24 16:58:59 - __main__ - INFO - üì± –ë–æ—Ç –≥–æ—Ç–æ–≤ –∫ –ø—Ä–∏–µ–º—É —Å–æ–æ–±—â–µ–Ω–∏–π
2025-06-24 16:58:59 - __main__ - INFO - üîó –ù–∞–∂–º–∏—Ç–µ Ctrl+C –¥–ª—è –æ—Å—Ç–∞–Ω–æ–≤–∫–∏
2025-06-24 16:59:00 - apscheduler.scheduler - INFO - Scheduler started
2025-06-24 18:18:20 - telegram.ext.Updater - ERROR - Error while getting Updates: httpx.ReadError: 
2025-06-24 18:18:20 - telegram.ext.Application - ERROR - No error handlers are registered, logging exception.
Traceback (most recent call last):
  File "C:\Users\F12$\AppData\Local\Programs\Python\Python311\Lib\site-packages\httpx\_transports\default.py", line 66, in map_httpcore_exceptions
    yield
  File "C:\Users\F12$\AppData\Local\Programs\Python\Python311\Lib\site-packages\httpx\_transports\default.py", line 366, in handle_async_request
    resp = await self._pool.handle_async_request(req)
           ^^^^^^^^^^^^^^^^^^^^^^^^^^^^^^^^^^^^^^^^^^
  File "C:\Users\F12$\AppData\Local\Programs\Python\Python311\Lib\site-packages\httpcore\_async\connection_pool.py", line 256, in handle_async_request
    raise exc from None
  File "C:\Users\F12$\AppData\Local\Programs\Python\Python311\Lib\site-packages\httpcore\_async\connection_pool.py", line 236, in handle_async_request
    response = await connection.handle_async_request(
               ^^^^^^^^^^^^^^^^^^^^^^^^^^^^^^^^^^^^^^
  File "C:\Users\F12$\AppData\Local\Programs\Python\Python311\Lib\site-packages\httpcore\_async\connection.py", line 103, in handle_async_request
    return await self._connection.handle_async_request(request)
           ^^^^^^^^^^^^^^^^^^^^^^^^^^^^^^^^^^^^^^^^^^^^^^^^^^^^
  File "C:\Users\F12$\AppData\Local\Programs\Python\Python311\Lib\site-packages\httpcore\_async\http11.py", line 136, in handle_async_request
    raise exc
  File "C:\Users\F12$\AppData\Local\Programs\Python\Python311\Lib\site-packages\httpcore\_async\http11.py", line 106, in handle_async_request
    ) = await self._receive_response_headers(**kwargs)
        ^^^^^^^^^^^^^^^^^^^^^^^^^^^^^^^^^^^^^^^^^^^^^^
  File "C:\Users\F12$\AppData\Local\Programs\Python\Python311\Lib\site-packages\httpcore\_async\http11.py", line 177, in _receive_response_headers
    event = await self._receive_event(timeout=timeout)
            ^^^^^^^^^^^^^^^^^^^^^^^^^^^^^^^^^^^^^^^^^^
  File "C:\Users\F12$\AppData\Local\Programs\Python\Python311\Lib\site-packages\httpcore\_async\http11.py", line 217, in _receive_event
    data = await self._network_stream.read(
           ^^^^^^^^^^^^^^^^^^^^^^^^^^^^^^^^
  File "C:\Users\F12$\AppData\Local\Programs\Python\Python311\Lib\site-packages\httpcore\_backends\anyio.py", line 32, in read
    with map_exceptions(exc_map):
  File "C:\Users\F12$\AppData\Local\Programs\Python\Python311\Lib\contextlib.py", line 158, in __exit__
    self.gen.throw(typ, value, traceback)
  File "C:\Users\F12$\AppData\Local\Programs\Python\Python311\Lib\site-packages\httpcore\_exceptions.py", line 14, in map_exceptions
    raise to_exc(exc) from exc
httpcore.ReadError

The above exception was the direct cause of the following exception:

Traceback (most recent call last):
  File "C:\Users\F12$\AppData\Local\Programs\Python\Python311\Lib\site-packages\telegram\request\_httpxrequest.py", line 268, in do_request
    res = await self._client.request(
          ^^^^^^^^^^^^^^^^^^^^^^^^^^^
  File "C:\Users\F12$\AppData\Local\Programs\Python\Python311\Lib\site-packages\httpx\_client.py", line 1530, in request
    return await self.send(request, auth=auth, follow_redirects=follow_redirects)
           ^^^^^^^^^^^^^^^^^^^^^^^^^^^^^^^^^^^^^^^^^^^^^^^^^^^^^^^^^^^^^^^^^^^^^^
  File "C:\Users\F12$\AppData\Local\Programs\Python\Python311\Lib\site-packages\httpx\_client.py", line 1617, in send
    response = await self._send_handling_auth(
               ^^^^^^^^^^^^^^^^^^^^^^^^^^^^^^^
  File "C:\Users\F12$\AppData\Local\Programs\Python\Python311\Lib\site-packages\httpx\_client.py", line 1645, in _send_handling_auth
    response = await self._send_handling_redirects(
               ^^^^^^^^^^^^^^^^^^^^^^^^^^^^^^^^^^^^
  File "C:\Users\F12$\AppData\Local\Programs\Python\Python311\Lib\site-packages\httpx\_client.py", line 1682, in _send_handling_redirects
    response = await self._send_single_request(request)
               ^^^^^^^^^^^^^^^^^^^^^^^^^^^^^^^^^^^^^^^^
  File "C:\Users\F12$\AppData\Local\Programs\Python\Python311\Lib\site-packages\httpx\_client.py", line 1719, in _send_single_request
    response = await transport.handle_async_request(request)
               ^^^^^^^^^^^^^^^^^^^^^^^^^^^^^^^^^^^^^^^^^^^^^
  File "C:\Users\F12$\AppData\Local\Programs\Python\Python311\Lib\site-packages\httpx\_transports\default.py", line 365, in handle_async_request
    with map_httpcore_exceptions():
  File "C:\Users\F12$\AppData\Local\Programs\Python\Python311\Lib\contextlib.py", line 158, in __exit__
    self.gen.throw(typ, value, traceback)
  File "C:\Users\F12$\AppData\Local\Programs\Python\Python311\Lib\site-packages\httpx\_transports\default.py", line 83, in map_httpcore_exceptions
    raise mapped_exc(message) from exc
httpx.ReadError

The above exception was the direct cause of the following exception:

Traceback (most recent call last):
  File "C:\Users\F12$\AppData\Local\Programs\Python\Python311\Lib\site-packages\telegram\ext\_updater.py", line 688, in _network_loop_retry
    if not await action_cb():
           ^^^^^^^^^^^^^^^^^
  File "C:\Users\F12$\AppData\Local\Programs\Python\Python311\Lib\site-packages\telegram\ext\_updater.py", line 384, in polling_action_cb
    raise exc
  File "C:\Users\F12$\AppData\Local\Programs\Python\Python311\Lib\site-packages\telegram\ext\_updater.py", line 373, in polling_action_cb
    updates = await self.bot.get_updates(
              ^^^^^^^^^^^^^^^^^^^^^^^^^^^
  File "C:\Users\F12$\AppData\Local\Programs\Python\Python311\Lib\site-packages\telegram\ext\_extbot.py", line 558, in get_updates
    updates = await super().get_updates(
              ^^^^^^^^^^^^^^^^^^^^^^^^^^
  File "C:\Users\F12$\AppData\Local\Programs\Python\Python311\Lib\site-packages\telegram\_bot.py", line 525, in decorator
    result = await func(self, *args, **kwargs)  # skipcq: PYL-E1102
             ^^^^^^^^^^^^^^^^^^^^^^^^^^^^^^^^^
  File "C:\Users\F12$\AppData\Local\Programs\Python\Python311\Lib\site-packages\telegram\_bot.py", line 3584, in get_updates
    await self._post(
  File "C:\Users\F12$\AppData\Local\Programs\Python\Python311\Lib\site-packages\telegram\_bot.py", line 613, in _post
    return await self._do_post(
           ^^^^^^^^^^^^^^^^^^^^
  File "C:\Users\F12$\AppData\Local\Programs\Python\Python311\Lib\site-packages\telegram\ext\_extbot.py", line 340, in _do_post
    return await super()._do_post(
           ^^^^^^^^^^^^^^^^^^^^^^^
  File "C:\Users\F12$\AppData\Local\Programs\Python\Python311\Lib\site-packages\telegram\_bot.py", line 641, in _do_post
    return await request.post(
           ^^^^^^^^^^^^^^^^^^^
  File "C:\Users\F12$\AppData\Local\Programs\Python\Python311\Lib\site-packages\telegram\request\_baserequest.py", line 200, in post
    result = await self._request_wrapper(
             ^^^^^^^^^^^^^^^^^^^^^^^^^^^^
  File "C:\Users\F12$\AppData\Local\Programs\Python\Python311\Lib\site-packages\telegram\request\_baserequest.py", line 340, in _request_wrapper
    raise exc
  File "C:\Users\F12$\AppData\Local\Programs\Python\Python311\Lib\site-packages\telegram\request\_baserequest.py", line 330, in _request_wrapper
    code, payload = await self.do_request(
                    ^^^^^^^^^^^^^^^^^^^^^^
  File "C:\Users\F12$\AppData\Local\Programs\Python\Python311\Lib\site-packages\telegram\request\_httpxrequest.py", line 292, in do_request
    raise NetworkError(f"httpx.{err.__class__.__name__}: {err}") from err
telegram.error.NetworkError: httpx.ReadError: 
2025-06-24 18:18:21 - telegram.ext.Updater - ERROR - Error while getting Updates: httpx.ConnectError: [Errno 11001] getaddrinfo failed
2025-06-24 18:18:21 - telegram.ext.Application - ERROR - No error handlers are registered, logging exception.
Traceback (most recent call last):
  File "C:\Users\F12$\AppData\Local\Programs\Python\Python311\Lib\site-packages\httpx\_transports\default.py", line 66, in map_httpcore_exceptions
    yield
  File "C:\Users\F12$\AppData\Local\Programs\Python\Python311\Lib\site-packages\httpx\_transports\default.py", line 366, in handle_async_request
    resp = await self._pool.handle_async_request(req)
           ^^^^^^^^^^^^^^^^^^^^^^^^^^^^^^^^^^^^^^^^^^
  File "C:\Users\F12$\AppData\Local\Programs\Python\Python311\Lib\site-packages\httpcore\_async\connection_pool.py", line 256, in handle_async_request
    raise exc from None
  File "C:\Users\F12$\AppData\Local\Programs\Python\Python311\Lib\site-packages\httpcore\_async\connection_pool.py", line 236, in handle_async_request
    response = await connection.handle_async_request(
               ^^^^^^^^^^^^^^^^^^^^^^^^^^^^^^^^^^^^^^
  File "C:\Users\F12$\AppData\Local\Programs\Python\Python311\Lib\site-packages\httpcore\_async\connection.py", line 101, in handle_async_request
    raise exc
  File "C:\Users\F12$\AppData\Local\Programs\Python\Python311\Lib\site-packages\httpcore\_async\connection.py", line 78, in handle_async_request
    stream = await self._connect(request)
             ^^^^^^^^^^^^^^^^^^^^^^^^^^^^
  File "C:\Users\F12$\AppData\Local\Programs\Python\Python311\Lib\site-packages\httpcore\_async\connection.py", line 124, in _connect
    stream = await self._network_backend.connect_tcp(**kwargs)
             ^^^^^^^^^^^^^^^^^^^^^^^^^^^^^^^^^^^^^^^^^^^^^^^^^
  File "C:\Users\F12$\AppData\Local\Programs\Python\Python311\Lib\site-packages\httpcore\_backends\auto.py", line 31, in connect_tcp
    return await self._backend.connect_tcp(
           ^^^^^^^^^^^^^^^^^^^^^^^^^^^^^^^^
  File "C:\Users\F12$\AppData\Local\Programs\Python\Python311\Lib\site-packages\httpcore\_backends\anyio.py", line 113, in connect_tcp
    with map_exceptions(exc_map):
  File "C:\Users\F12$\AppData\Local\Programs\Python\Python311\Lib\contextlib.py", line 158, in __exit__
    self.gen.throw(typ, value, traceback)
  File "C:\Users\F12$\AppData\Local\Programs\Python\Python311\Lib\site-packages\httpcore\_exceptions.py", line 14, in map_exceptions
    raise to_exc(exc) from exc
httpcore.ConnectError: [Errno 11001] getaddrinfo failed

The above exception was the direct cause of the following exception:

Traceback (most recent call last):
  File "C:\Users\F12$\AppData\Local\Programs\Python\Python311\Lib\site-packages\telegram\request\_httpxrequest.py", line 268, in do_request
    res = await self._client.request(
          ^^^^^^^^^^^^^^^^^^^^^^^^^^^
  File "C:\Users\F12$\AppData\Local\Programs\Python\Python311\Lib\site-packages\httpx\_client.py", line 1530, in request
    return await self.send(request, auth=auth, follow_redirects=follow_redirects)
           ^^^^^^^^^^^^^^^^^^^^^^^^^^^^^^^^^^^^^^^^^^^^^^^^^^^^^^^^^^^^^^^^^^^^^^
  File "C:\Users\F12$\AppData\Local\Programs\Python\Python311\Lib\site-packages\httpx\_client.py", line 1617, in send
    response = await self._send_handling_auth(
               ^^^^^^^^^^^^^^^^^^^^^^^^^^^^^^^
  File "C:\Users\F12$\AppData\Local\Programs\Python\Python311\Lib\site-packages\httpx\_client.py", line 1645, in _send_handling_auth
    response = await self._send_handling_redirects(
               ^^^^^^^^^^^^^^^^^^^^^^^^^^^^^^^^^^^^
  File "C:\Users\F12$\AppData\Local\Programs\Python\Python311\Lib\site-packages\httpx\_client.py", line 1682, in _send_handling_redirects
    response = await self._send_single_request(request)
               ^^^^^^^^^^^^^^^^^^^^^^^^^^^^^^^^^^^^^^^^
  File "C:\Users\F12$\AppData\Local\Programs\Python\Python311\Lib\site-packages\httpx\_client.py", line 1719, in _send_single_request
    response = await transport.handle_async_request(request)
               ^^^^^^^^^^^^^^^^^^^^^^^^^^^^^^^^^^^^^^^^^^^^^
  File "C:\Users\F12$\AppData\Local\Programs\Python\Python311\Lib\site-packages\httpx\_transports\default.py", line 365, in handle_async_request
    with map_httpcore_exceptions():
  File "C:\Users\F12$\AppData\Local\Programs\Python\Python311\Lib\contextlib.py", line 158, in __exit__
    self.gen.throw(typ, value, traceback)
  File "C:\Users\F12$\AppData\Local\Programs\Python\Python311\Lib\site-packages\httpx\_transports\default.py", line 83, in map_httpcore_exceptions
    raise mapped_exc(message) from exc
httpx.ConnectError: [Errno 11001] getaddrinfo failed

The above exception was the direct cause of the following exception:

Traceback (most recent call last):
  File "C:\Users\F12$\AppData\Local\Programs\Python\Python311\Lib\site-packages\telegram\ext\_updater.py", line 688, in _network_loop_retry
    if not await action_cb():
           ^^^^^^^^^^^^^^^^^
  File "C:\Users\F12$\AppData\Local\Programs\Python\Python311\Lib\site-packages\telegram\ext\_updater.py", line 384, in polling_action_cb
    raise exc
  File "C:\Users\F12$\AppData\Local\Programs\Python\Python311\Lib\site-packages\telegram\ext\_updater.py", line 373, in polling_action_cb
    updates = await self.bot.get_updates(
              ^^^^^^^^^^^^^^^^^^^^^^^^^^^
  File "C:\Users\F12$\AppData\Local\Programs\Python\Python311\Lib\site-packages\telegram\ext\_extbot.py", line 558, in get_updates
    updates = await super().get_updates(
              ^^^^^^^^^^^^^^^^^^^^^^^^^^
  File "C:\Users\F12$\AppData\Local\Programs\Python\Python311\Lib\site-packages\telegram\_bot.py", line 525, in decorator
    result = await func(self, *args, **kwargs)  # skipcq: PYL-E1102
             ^^^^^^^^^^^^^^^^^^^^^^^^^^^^^^^^^
  File "C:\Users\F12$\AppData\Local\Programs\Python\Python311\Lib\site-packages\telegram\_bot.py", line 3584, in get_updates
    await self._post(
  File "C:\Users\F12$\AppData\Local\Programs\Python\Python311\Lib\site-packages\telegram\_bot.py", line 613, in _post
    return await self._do_post(
           ^^^^^^^^^^^^^^^^^^^^
  File "C:\Users\F12$\AppData\Local\Programs\Python\Python311\Lib\site-packages\telegram\ext\_extbot.py", line 340, in _do_post
    return await super()._do_post(
           ^^^^^^^^^^^^^^^^^^^^^^^
  File "C:\Users\F12$\AppData\Local\Programs\Python\Python311\Lib\site-packages\telegram\_bot.py", line 641, in _do_post
    return await request.post(
           ^^^^^^^^^^^^^^^^^^^
  File "C:\Users\F12$\AppData\Local\Programs\Python\Python311\Lib\site-packages\telegram\request\_baserequest.py", line 200, in post
    result = await self._request_wrapper(
             ^^^^^^^^^^^^^^^^^^^^^^^^^^^^
  File "C:\Users\F12$\AppData\Local\Programs\Python\Python311\Lib\site-packages\telegram\request\_baserequest.py", line 340, in _request_wrapper
    raise exc
  File "C:\Users\F12$\AppData\Local\Programs\Python\Python311\Lib\site-packages\telegram\request\_baserequest.py", line 330, in _request_wrapper
    code, payload = await self.do_request(
                    ^^^^^^^^^^^^^^^^^^^^^^
  File "C:\Users\F12$\AppData\Local\Programs\Python\Python311\Lib\site-packages\telegram\request\_httpxrequest.py", line 292, in do_request
    raise NetworkError(f"httpx.{err.__class__.__name__}: {err}") from err
telegram.error.NetworkError: httpx.ConnectError: [Errno 11001] getaddrinfo failed
2025-06-24 18:27:18 - telegram.ext.Updater - ERROR - Error while getting Updates: httpx.ConnectError: [Errno 11001] getaddrinfo failed
2025-06-24 18:27:18 - telegram.ext.Application - ERROR - No error handlers are registered, logging exception.
Traceback (most recent call last):
  File "C:\Users\F12$\AppData\Local\Programs\Python\Python311\Lib\site-packages\httpx\_transports\default.py", line 66, in map_httpcore_exceptions
    yield
  File "C:\Users\F12$\AppData\Local\Programs\Python\Python311\Lib\site-packages\httpx\_transports\default.py", line 366, in handle_async_request
    resp = await self._pool.handle_async_request(req)
           ^^^^^^^^^^^^^^^^^^^^^^^^^^^^^^^^^^^^^^^^^^
  File "C:\Users\F12$\AppData\Local\Programs\Python\Python311\Lib\site-packages\httpcore\_async\connection_pool.py", line 256, in handle_async_request
    raise exc from None
  File "C:\Users\F12$\AppData\Local\Programs\Python\Python311\Lib\site-packages\httpcore\_async\connection_pool.py", line 236, in handle_async_request
    response = await connection.handle_async_request(
               ^^^^^^^^^^^^^^^^^^^^^^^^^^^^^^^^^^^^^^
  File "C:\Users\F12$\AppData\Local\Programs\Python\Python311\Lib\site-packages\httpcore\_async\connection.py", line 101, in handle_async_request
    raise exc
  File "C:\Users\F12$\AppData\Local\Programs\Python\Python311\Lib\site-packages\httpcore\_async\connection.py", line 78, in handle_async_request
    stream = await self._connect(request)
             ^^^^^^^^^^^^^^^^^^^^^^^^^^^^
  File "C:\Users\F12$\AppData\Local\Programs\Python\Python311\Lib\site-packages\httpcore\_async\connection.py", line 124, in _connect
    stream = await self._network_backend.connect_tcp(**kwargs)
             ^^^^^^^^^^^^^^^^^^^^^^^^^^^^^^^^^^^^^^^^^^^^^^^^^
  File "C:\Users\F12$\AppData\Local\Programs\Python\Python311\Lib\site-packages\httpcore\_backends\auto.py", line 31, in connect_tcp
    return await self._backend.connect_tcp(
           ^^^^^^^^^^^^^^^^^^^^^^^^^^^^^^^^
  File "C:\Users\F12$\AppData\Local\Programs\Python\Python311\Lib\site-packages\httpcore\_backends\anyio.py", line 113, in connect_tcp
    with map_exceptions(exc_map):
  File "C:\Users\F12$\AppData\Local\Programs\Python\Python311\Lib\contextlib.py", line 158, in __exit__
    self.gen.throw(typ, value, traceback)
  File "C:\Users\F12$\AppData\Local\Programs\Python\Python311\Lib\site-packages\httpcore\_exceptions.py", line 14, in map_exceptions
    raise to_exc(exc) from exc
httpcore.ConnectError: [Errno 11001] getaddrinfo failed

The above exception was the direct cause of the following exception:

Traceback (most recent call last):
  File "C:\Users\F12$\AppData\Local\Programs\Python\Python311\Lib\site-packages\telegram\request\_httpxrequest.py", line 268, in do_request
    res = await self._client.request(
          ^^^^^^^^^^^^^^^^^^^^^^^^^^^
  File "C:\Users\F12$\AppData\Local\Programs\Python\Python311\Lib\site-packages\httpx\_client.py", line 1530, in request
    return await self.send(request, auth=auth, follow_redirects=follow_redirects)
           ^^^^^^^^^^^^^^^^^^^^^^^^^^^^^^^^^^^^^^^^^^^^^^^^^^^^^^^^^^^^^^^^^^^^^^
  File "C:\Users\F12$\AppData\Local\Programs\Python\Python311\Lib\site-packages\httpx\_client.py", line 1617, in send
    response = await self._send_handling_auth(
               ^^^^^^^^^^^^^^^^^^^^^^^^^^^^^^^
  File "C:\Users\F12$\AppData\Local\Programs\Python\Python311\Lib\site-packages\httpx\_client.py", line 1645, in _send_handling_auth
    response = await self._send_handling_redirects(
               ^^^^^^^^^^^^^^^^^^^^^^^^^^^^^^^^^^^^
  File "C:\Users\F12$\AppData\Local\Programs\Python\Python311\Lib\site-packages\httpx\_client.py", line 1682, in _send_handling_redirects
    response = await self._send_single_request(request)
               ^^^^^^^^^^^^^^^^^^^^^^^^^^^^^^^^^^^^^^^^
  File "C:\Users\F12$\AppData\Local\Programs\Python\Python311\Lib\site-packages\httpx\_client.py", line 1719, in _send_single_request
    response = await transport.handle_async_request(request)
               ^^^^^^^^^^^^^^^^^^^^^^^^^^^^^^^^^^^^^^^^^^^^^
  File "C:\Users\F12$\AppData\Local\Programs\Python\Python311\Lib\site-packages\httpx\_transports\default.py", line 365, in handle_async_request
    with map_httpcore_exceptions():
  File "C:\Users\F12$\AppData\Local\Programs\Python\Python311\Lib\contextlib.py", line 158, in __exit__
    self.gen.throw(typ, value, traceback)
  File "C:\Users\F12$\AppData\Local\Programs\Python\Python311\Lib\site-packages\httpx\_transports\default.py", line 83, in map_httpcore_exceptions
    raise mapped_exc(message) from exc
httpx.ConnectError: [Errno 11001] getaddrinfo failed

The above exception was the direct cause of the following exception:

Traceback (most recent call last):
  File "C:\Users\F12$\AppData\Local\Programs\Python\Python311\Lib\site-packages\telegram\ext\_updater.py", line 688, in _network_loop_retry
    if not await action_cb():
           ^^^^^^^^^^^^^^^^^
  File "C:\Users\F12$\AppData\Local\Programs\Python\Python311\Lib\site-packages\telegram\ext\_updater.py", line 384, in polling_action_cb
    raise exc
  File "C:\Users\F12$\AppData\Local\Programs\Python\Python311\Lib\site-packages\telegram\ext\_updater.py", line 373, in polling_action_cb
    updates = await self.bot.get_updates(
              ^^^^^^^^^^^^^^^^^^^^^^^^^^^
  File "C:\Users\F12$\AppData\Local\Programs\Python\Python311\Lib\site-packages\telegram\ext\_extbot.py", line 558, in get_updates
    updates = await super().get_updates(
              ^^^^^^^^^^^^^^^^^^^^^^^^^^
  File "C:\Users\F12$\AppData\Local\Programs\Python\Python311\Lib\site-packages\telegram\_bot.py", line 525, in decorator
    result = await func(self, *args, **kwargs)  # skipcq: PYL-E1102
             ^^^^^^^^^^^^^^^^^^^^^^^^^^^^^^^^^
  File "C:\Users\F12$\AppData\Local\Programs\Python\Python311\Lib\site-packages\telegram\_bot.py", line 3584, in get_updates
    await self._post(
  File "C:\Users\F12$\AppData\Local\Programs\Python\Python311\Lib\site-packages\telegram\_bot.py", line 613, in _post
    return await self._do_post(
           ^^^^^^^^^^^^^^^^^^^^
  File "C:\Users\F12$\AppData\Local\Programs\Python\Python311\Lib\site-packages\telegram\ext\_extbot.py", line 340, in _do_post
    return await super()._do_post(
           ^^^^^^^^^^^^^^^^^^^^^^^
  File "C:\Users\F12$\AppData\Local\Programs\Python\Python311\Lib\site-packages\telegram\_bot.py", line 641, in _do_post
    return await request.post(
           ^^^^^^^^^^^^^^^^^^^
  File "C:\Users\F12$\AppData\Local\Programs\Python\Python311\Lib\site-packages\telegram\request\_baserequest.py", line 200, in post
    result = await self._request_wrapper(
             ^^^^^^^^^^^^^^^^^^^^^^^^^^^^
  File "C:\Users\F12$\AppData\Local\Programs\Python\Python311\Lib\site-packages\telegram\request\_baserequest.py", line 340, in _request_wrapper
    raise exc
  File "C:\Users\F12$\AppData\Local\Programs\Python\Python311\Lib\site-packages\telegram\request\_baserequest.py", line 330, in _request_wrapper
    code, payload = await self.do_request(
                    ^^^^^^^^^^^^^^^^^^^^^^
  File "C:\Users\F12$\AppData\Local\Programs\Python\Python311\Lib\site-packages\telegram\request\_httpxrequest.py", line 292, in do_request
    raise NetworkError(f"httpx.{err.__class__.__name__}: {err}") from err
telegram.error.NetworkError: httpx.ConnectError: [Errno 11001] getaddrinfo failed
2025-06-24 18:27:20 - telegram.ext.Updater - ERROR - Error while getting Updates: httpx.ConnectError: [Errno 11001] getaddrinfo failed
2025-06-24 18:27:20 - telegram.ext.Application - ERROR - No error handlers are registered, logging exception.
Traceback (most recent call last):
  File "C:\Users\F12$\AppData\Local\Programs\Python\Python311\Lib\site-packages\httpx\_transports\default.py", line 66, in map_httpcore_exceptions
    yield
  File "C:\Users\F12$\AppData\Local\Programs\Python\Python311\Lib\site-packages\httpx\_transports\default.py", line 366, in handle_async_request
    resp = await self._pool.handle_async_request(req)
           ^^^^^^^^^^^^^^^^^^^^^^^^^^^^^^^^^^^^^^^^^^
  File "C:\Users\F12$\AppData\Local\Programs\Python\Python311\Lib\site-packages\httpcore\_async\connection_pool.py", line 256, in handle_async_request
    raise exc from None
  File "C:\Users\F12$\AppData\Local\Programs\Python\Python311\Lib\site-packages\httpcore\_async\connection_pool.py", line 236, in handle_async_request
    response = await connection.handle_async_request(
               ^^^^^^^^^^^^^^^^^^^^^^^^^^^^^^^^^^^^^^
  File "C:\Users\F12$\AppData\Local\Programs\Python\Python311\Lib\site-packages\httpcore\_async\connection.py", line 101, in handle_async_request
    raise exc
  File "C:\Users\F12$\AppData\Local\Programs\Python\Python311\Lib\site-packages\httpcore\_async\connection.py", line 78, in handle_async_request
    stream = await self._connect(request)
             ^^^^^^^^^^^^^^^^^^^^^^^^^^^^
  File "C:\Users\F12$\AppData\Local\Programs\Python\Python311\Lib\site-packages\httpcore\_async\connection.py", line 124, in _connect
    stream = await self._network_backend.connect_tcp(**kwargs)
             ^^^^^^^^^^^^^^^^^^^^^^^^^^^^^^^^^^^^^^^^^^^^^^^^^
  File "C:\Users\F12$\AppData\Local\Programs\Python\Python311\Lib\site-packages\httpcore\_backends\auto.py", line 31, in connect_tcp
    return await self._backend.connect_tcp(
           ^^^^^^^^^^^^^^^^^^^^^^^^^^^^^^^^
  File "C:\Users\F12$\AppData\Local\Programs\Python\Python311\Lib\site-packages\httpcore\_backends\anyio.py", line 113, in connect_tcp
    with map_exceptions(exc_map):
  File "C:\Users\F12$\AppData\Local\Programs\Python\Python311\Lib\contextlib.py", line 158, in __exit__
    self.gen.throw(typ, value, traceback)
  File "C:\Users\F12$\AppData\Local\Programs\Python\Python311\Lib\site-packages\httpcore\_exceptions.py", line 14, in map_exceptions
    raise to_exc(exc) from exc
httpcore.ConnectError: [Errno 11001] getaddrinfo failed

The above exception was the direct cause of the following exception:

Traceback (most recent call last):
  File "C:\Users\F12$\AppData\Local\Programs\Python\Python311\Lib\site-packages\telegram\request\_httpxrequest.py", line 268, in do_request
    res = await self._client.request(
          ^^^^^^^^^^^^^^^^^^^^^^^^^^^
  File "C:\Users\F12$\AppData\Local\Programs\Python\Python311\Lib\site-packages\httpx\_client.py", line 1530, in request
    return await self.send(request, auth=auth, follow_redirects=follow_redirects)
           ^^^^^^^^^^^^^^^^^^^^^^^^^^^^^^^^^^^^^^^^^^^^^^^^^^^^^^^^^^^^^^^^^^^^^^
  File "C:\Users\F12$\AppData\Local\Programs\Python\Python311\Lib\site-packages\httpx\_client.py", line 1617, in send
    response = await self._send_handling_auth(
               ^^^^^^^^^^^^^^^^^^^^^^^^^^^^^^^
  File "C:\Users\F12$\AppData\Local\Programs\Python\Python311\Lib\site-packages\httpx\_client.py", line 1645, in _send_handling_auth
    response = await self._send_handling_redirects(
               ^^^^^^^^^^^^^^^^^^^^^^^^^^^^^^^^^^^^
  File "C:\Users\F12$\AppData\Local\Programs\Python\Python311\Lib\site-packages\httpx\_client.py", line 1682, in _send_handling_redirects
    response = await self._send_single_request(request)
               ^^^^^^^^^^^^^^^^^^^^^^^^^^^^^^^^^^^^^^^^
  File "C:\Users\F12$\AppData\Local\Programs\Python\Python311\Lib\site-packages\httpx\_client.py", line 1719, in _send_single_request
    response = await transport.handle_async_request(request)
               ^^^^^^^^^^^^^^^^^^^^^^^^^^^^^^^^^^^^^^^^^^^^^
  File "C:\Users\F12$\AppData\Local\Programs\Python\Python311\Lib\site-packages\httpx\_transports\default.py", line 365, in handle_async_request
    with map_httpcore_exceptions():
  File "C:\Users\F12$\AppData\Local\Programs\Python\Python311\Lib\contextlib.py", line 158, in __exit__
    self.gen.throw(typ, value, traceback)
  File "C:\Users\F12$\AppData\Local\Programs\Python\Python311\Lib\site-packages\httpx\_transports\default.py", line 83, in map_httpcore_exceptions
    raise mapped_exc(message) from exc
httpx.ConnectError: [Errno 11001] getaddrinfo failed

The above exception was the direct cause of the following exception:

Traceback (most recent call last):
  File "C:\Users\F12$\AppData\Local\Programs\Python\Python311\Lib\site-packages\telegram\ext\_updater.py", line 688, in _network_loop_retry
    if not await action_cb():
           ^^^^^^^^^^^^^^^^^
  File "C:\Users\F12$\AppData\Local\Programs\Python\Python311\Lib\site-packages\telegram\ext\_updater.py", line 384, in polling_action_cb
    raise exc
  File "C:\Users\F12$\AppData\Local\Programs\Python\Python311\Lib\site-packages\telegram\ext\_updater.py", line 373, in polling_action_cb
    updates = await self.bot.get_updates(
              ^^^^^^^^^^^^^^^^^^^^^^^^^^^
  File "C:\Users\F12$\AppData\Local\Programs\Python\Python311\Lib\site-packages\telegram\ext\_extbot.py", line 558, in get_updates
    updates = await super().get_updates(
              ^^^^^^^^^^^^^^^^^^^^^^^^^^
  File "C:\Users\F12$\AppData\Local\Programs\Python\Python311\Lib\site-packages\telegram\_bot.py", line 525, in decorator
    result = await func(self, *args, **kwargs)  # skipcq: PYL-E1102
             ^^^^^^^^^^^^^^^^^^^^^^^^^^^^^^^^^
  File "C:\Users\F12$\AppData\Local\Programs\Python\Python311\Lib\site-packages\telegram\_bot.py", line 3584, in get_updates
    await self._post(
  File "C:\Users\F12$\AppData\Local\Programs\Python\Python311\Lib\site-packages\telegram\_bot.py", line 613, in _post
    return await self._do_post(
           ^^^^^^^^^^^^^^^^^^^^
  File "C:\Users\F12$\AppData\Local\Programs\Python\Python311\Lib\site-packages\telegram\ext\_extbot.py", line 340, in _do_post
    return await super()._do_post(
           ^^^^^^^^^^^^^^^^^^^^^^^
  File "C:\Users\F12$\AppData\Local\Programs\Python\Python311\Lib\site-packages\telegram\_bot.py", line 641, in _do_post
    return await request.post(
           ^^^^^^^^^^^^^^^^^^^
  File "C:\Users\F12$\AppData\Local\Programs\Python\Python311\Lib\site-packages\telegram\request\_baserequest.py", line 200, in post
    result = await self._request_wrapper(
             ^^^^^^^^^^^^^^^^^^^^^^^^^^^^
  File "C:\Users\F12$\AppData\Local\Programs\Python\Python311\Lib\site-packages\telegram\request\_baserequest.py", line 340, in _request_wrapper
    raise exc
  File "C:\Users\F12$\AppData\Local\Programs\Python\Python311\Lib\site-packages\telegram\request\_baserequest.py", line 330, in _request_wrapper
    code, payload = await self.do_request(
                    ^^^^^^^^^^^^^^^^^^^^^^
  File "C:\Users\F12$\AppData\Local\Programs\Python\Python311\Lib\site-packages\telegram\request\_httpxrequest.py", line 292, in do_request
    raise NetworkError(f"httpx.{err.__class__.__name__}: {err}") from err
telegram.error.NetworkError: httpx.ConnectError: [Errno 11001] getaddrinfo failed
2025-06-24 18:49:02 - telegram.ext.Updater - ERROR - Error while getting Updates: httpx.ConnectError: [Errno 11001] getaddrinfo failed
2025-06-24 18:49:02 - telegram.ext.Application - ERROR - No error handlers are registered, logging exception.
Traceback (most recent call last):
  File "C:\Users\F12$\AppData\Local\Programs\Python\Python311\Lib\site-packages\httpx\_transports\default.py", line 66, in map_httpcore_exceptions
    yield
  File "C:\Users\F12$\AppData\Local\Programs\Python\Python311\Lib\site-packages\httpx\_transports\default.py", line 366, in handle_async_request
    resp = await self._pool.handle_async_request(req)
           ^^^^^^^^^^^^^^^^^^^^^^^^^^^^^^^^^^^^^^^^^^
  File "C:\Users\F12$\AppData\Local\Programs\Python\Python311\Lib\site-packages\httpcore\_async\connection_pool.py", line 256, in handle_async_request
    raise exc from None
  File "C:\Users\F12$\AppData\Local\Programs\Python\Python311\Lib\site-packages\httpcore\_async\connection_pool.py", line 236, in handle_async_request
    response = await connection.handle_async_request(
               ^^^^^^^^^^^^^^^^^^^^^^^^^^^^^^^^^^^^^^
  File "C:\Users\F12$\AppData\Local\Programs\Python\Python311\Lib\site-packages\httpcore\_async\connection.py", line 101, in handle_async_request
    raise exc
  File "C:\Users\F12$\AppData\Local\Programs\Python\Python311\Lib\site-packages\httpcore\_async\connection.py", line 78, in handle_async_request
    stream = await self._connect(request)
             ^^^^^^^^^^^^^^^^^^^^^^^^^^^^
  File "C:\Users\F12$\AppData\Local\Programs\Python\Python311\Lib\site-packages\httpcore\_async\connection.py", line 124, in _connect
    stream = await self._network_backend.connect_tcp(**kwargs)
             ^^^^^^^^^^^^^^^^^^^^^^^^^^^^^^^^^^^^^^^^^^^^^^^^^
  File "C:\Users\F12$\AppData\Local\Programs\Python\Python311\Lib\site-packages\httpcore\_backends\auto.py", line 31, in connect_tcp
    return await self._backend.connect_tcp(
           ^^^^^^^^^^^^^^^^^^^^^^^^^^^^^^^^
  File "C:\Users\F12$\AppData\Local\Programs\Python\Python311\Lib\site-packages\httpcore\_backends\anyio.py", line 113, in connect_tcp
    with map_exceptions(exc_map):
  File "C:\Users\F12$\AppData\Local\Programs\Python\Python311\Lib\contextlib.py", line 158, in __exit__
    self.gen.throw(typ, value, traceback)
  File "C:\Users\F12$\AppData\Local\Programs\Python\Python311\Lib\site-packages\httpcore\_exceptions.py", line 14, in map_exceptions
    raise to_exc(exc) from exc
httpcore.ConnectError: [Errno 11001] getaddrinfo failed

The above exception was the direct cause of the following exception:

Traceback (most recent call last):
  File "C:\Users\F12$\AppData\Local\Programs\Python\Python311\Lib\site-packages\telegram\request\_httpxrequest.py", line 268, in do_request
    res = await self._client.request(
          ^^^^^^^^^^^^^^^^^^^^^^^^^^^
  File "C:\Users\F12$\AppData\Local\Programs\Python\Python311\Lib\site-packages\httpx\_client.py", line 1530, in request
    return await self.send(request, auth=auth, follow_redirects=follow_redirects)
           ^^^^^^^^^^^^^^^^^^^^^^^^^^^^^^^^^^^^^^^^^^^^^^^^^^^^^^^^^^^^^^^^^^^^^^
  File "C:\Users\F12$\AppData\Local\Programs\Python\Python311\Lib\site-packages\httpx\_client.py", line 1617, in send
    response = await self._send_handling_auth(
               ^^^^^^^^^^^^^^^^^^^^^^^^^^^^^^^
  File "C:\Users\F12$\AppData\Local\Programs\Python\Python311\Lib\site-packages\httpx\_client.py", line 1645, in _send_handling_auth
    response = await self._send_handling_redirects(
               ^^^^^^^^^^^^^^^^^^^^^^^^^^^^^^^^^^^^
  File "C:\Users\F12$\AppData\Local\Programs\Python\Python311\Lib\site-packages\httpx\_client.py", line 1682, in _send_handling_redirects
    response = await self._send_single_request(request)
               ^^^^^^^^^^^^^^^^^^^^^^^^^^^^^^^^^^^^^^^^
  File "C:\Users\F12$\AppData\Local\Programs\Python\Python311\Lib\site-packages\httpx\_client.py", line 1719, in _send_single_request
    response = await transport.handle_async_request(request)
               ^^^^^^^^^^^^^^^^^^^^^^^^^^^^^^^^^^^^^^^^^^^^^
  File "C:\Users\F12$\AppData\Local\Programs\Python\Python311\Lib\site-packages\httpx\_transports\default.py", line 365, in handle_async_request
    with map_httpcore_exceptions():
  File "C:\Users\F12$\AppData\Local\Programs\Python\Python311\Lib\contextlib.py", line 158, in __exit__
    self.gen.throw(typ, value, traceback)
  File "C:\Users\F12$\AppData\Local\Programs\Python\Python311\Lib\site-packages\httpx\_transports\default.py", line 83, in map_httpcore_exceptions
    raise mapped_exc(message) from exc
httpx.ConnectError: [Errno 11001] getaddrinfo failed

The above exception was the direct cause of the following exception:

Traceback (most recent call last):
  File "C:\Users\F12$\AppData\Local\Programs\Python\Python311\Lib\site-packages\telegram\ext\_updater.py", line 688, in _network_loop_retry
    if not await action_cb():
           ^^^^^^^^^^^^^^^^^
  File "C:\Users\F12$\AppData\Local\Programs\Python\Python311\Lib\site-packages\telegram\ext\_updater.py", line 384, in polling_action_cb
    raise exc
  File "C:\Users\F12$\AppData\Local\Programs\Python\Python311\Lib\site-packages\telegram\ext\_updater.py", line 373, in polling_action_cb
    updates = await self.bot.get_updates(
              ^^^^^^^^^^^^^^^^^^^^^^^^^^^
  File "C:\Users\F12$\AppData\Local\Programs\Python\Python311\Lib\site-packages\telegram\ext\_extbot.py", line 558, in get_updates
    updates = await super().get_updates(
              ^^^^^^^^^^^^^^^^^^^^^^^^^^
  File "C:\Users\F12$\AppData\Local\Programs\Python\Python311\Lib\site-packages\telegram\_bot.py", line 525, in decorator
    result = await func(self, *args, **kwargs)  # skipcq: PYL-E1102
             ^^^^^^^^^^^^^^^^^^^^^^^^^^^^^^^^^
  File "C:\Users\F12$\AppData\Local\Programs\Python\Python311\Lib\site-packages\telegram\_bot.py", line 3584, in get_updates
    await self._post(
  File "C:\Users\F12$\AppData\Local\Programs\Python\Python311\Lib\site-packages\telegram\_bot.py", line 613, in _post
    return await self._do_post(
           ^^^^^^^^^^^^^^^^^^^^
  File "C:\Users\F12$\AppData\Local\Programs\Python\Python311\Lib\site-packages\telegram\ext\_extbot.py", line 340, in _do_post
    return await super()._do_post(
           ^^^^^^^^^^^^^^^^^^^^^^^
  File "C:\Users\F12$\AppData\Local\Programs\Python\Python311\Lib\site-packages\telegram\_bot.py", line 641, in _do_post
    return await request.post(
           ^^^^^^^^^^^^^^^^^^^
  File "C:\Users\F12$\AppData\Local\Programs\Python\Python311\Lib\site-packages\telegram\request\_baserequest.py", line 200, in post
    result = await self._request_wrapper(
             ^^^^^^^^^^^^^^^^^^^^^^^^^^^^
  File "C:\Users\F12$\AppData\Local\Programs\Python\Python311\Lib\site-packages\telegram\request\_baserequest.py", line 340, in _request_wrapper
    raise exc
  File "C:\Users\F12$\AppData\Local\Programs\Python\Python311\Lib\site-packages\telegram\request\_baserequest.py", line 330, in _request_wrapper
    code, payload = await self.do_request(
                    ^^^^^^^^^^^^^^^^^^^^^^
  File "C:\Users\F12$\AppData\Local\Programs\Python\Python311\Lib\site-packages\telegram\request\_httpxrequest.py", line 292, in do_request
    raise NetworkError(f"httpx.{err.__class__.__name__}: {err}") from err
telegram.error.NetworkError: httpx.ConnectError: [Errno 11001] getaddrinfo failed
2025-06-24 18:58:12 - telegram.ext.Updater - ERROR - Error while getting Updates: httpx.ConnectError: [Errno 11001] getaddrinfo failed
2025-06-24 18:58:12 - telegram.ext.Application - ERROR - No error handlers are registered, logging exception.
Traceback (most recent call last):
  File "C:\Users\F12$\AppData\Local\Programs\Python\Python311\Lib\site-packages\httpx\_transports\default.py", line 66, in map_httpcore_exceptions
    yield
  File "C:\Users\F12$\AppData\Local\Programs\Python\Python311\Lib\site-packages\httpx\_transports\default.py", line 366, in handle_async_request
    resp = await self._pool.handle_async_request(req)
           ^^^^^^^^^^^^^^^^^^^^^^^^^^^^^^^^^^^^^^^^^^
  File "C:\Users\F12$\AppData\Local\Programs\Python\Python311\Lib\site-packages\httpcore\_async\connection_pool.py", line 256, in handle_async_request
    raise exc from None
  File "C:\Users\F12$\AppData\Local\Programs\Python\Python311\Lib\site-packages\httpcore\_async\connection_pool.py", line 236, in handle_async_request
    response = await connection.handle_async_request(
               ^^^^^^^^^^^^^^^^^^^^^^^^^^^^^^^^^^^^^^
  File "C:\Users\F12$\AppData\Local\Programs\Python\Python311\Lib\site-packages\httpcore\_async\connection.py", line 101, in handle_async_request
    raise exc
  File "C:\Users\F12$\AppData\Local\Programs\Python\Python311\Lib\site-packages\httpcore\_async\connection.py", line 78, in handle_async_request
    stream = await self._connect(request)
             ^^^^^^^^^^^^^^^^^^^^^^^^^^^^
  File "C:\Users\F12$\AppData\Local\Programs\Python\Python311\Lib\site-packages\httpcore\_async\connection.py", line 124, in _connect
    stream = await self._network_backend.connect_tcp(**kwargs)
             ^^^^^^^^^^^^^^^^^^^^^^^^^^^^^^^^^^^^^^^^^^^^^^^^^
  File "C:\Users\F12$\AppData\Local\Programs\Python\Python311\Lib\site-packages\httpcore\_backends\auto.py", line 31, in connect_tcp
    return await self._backend.connect_tcp(
           ^^^^^^^^^^^^^^^^^^^^^^^^^^^^^^^^
  File "C:\Users\F12$\AppData\Local\Programs\Python\Python311\Lib\site-packages\httpcore\_backends\anyio.py", line 113, in connect_tcp
    with map_exceptions(exc_map):
  File "C:\Users\F12$\AppData\Local\Programs\Python\Python311\Lib\contextlib.py", line 158, in __exit__
    self.gen.throw(typ, value, traceback)
  File "C:\Users\F12$\AppData\Local\Programs\Python\Python311\Lib\site-packages\httpcore\_exceptions.py", line 14, in map_exceptions
    raise to_exc(exc) from exc
httpcore.ConnectError: [Errno 11001] getaddrinfo failed

The above exception was the direct cause of the following exception:

Traceback (most recent call last):
  File "C:\Users\F12$\AppData\Local\Programs\Python\Python311\Lib\site-packages\telegram\request\_httpxrequest.py", line 268, in do_request
    res = await self._client.request(
          ^^^^^^^^^^^^^^^^^^^^^^^^^^^
  File "C:\Users\F12$\AppData\Local\Programs\Python\Python311\Lib\site-packages\httpx\_client.py", line 1530, in request
    return await self.send(request, auth=auth, follow_redirects=follow_redirects)
           ^^^^^^^^^^^^^^^^^^^^^^^^^^^^^^^^^^^^^^^^^^^^^^^^^^^^^^^^^^^^^^^^^^^^^^
  File "C:\Users\F12$\AppData\Local\Programs\Python\Python311\Lib\site-packages\httpx\_client.py", line 1617, in send
    response = await self._send_handling_auth(
               ^^^^^^^^^^^^^^^^^^^^^^^^^^^^^^^
  File "C:\Users\F12$\AppData\Local\Programs\Python\Python311\Lib\site-packages\httpx\_client.py", line 1645, in _send_handling_auth
    response = await self._send_handling_redirects(
               ^^^^^^^^^^^^^^^^^^^^^^^^^^^^^^^^^^^^
  File "C:\Users\F12$\AppData\Local\Programs\Python\Python311\Lib\site-packages\httpx\_client.py", line 1682, in _send_handling_redirects
    response = await self._send_single_request(request)
               ^^^^^^^^^^^^^^^^^^^^^^^^^^^^^^^^^^^^^^^^
  File "C:\Users\F12$\AppData\Local\Programs\Python\Python311\Lib\site-packages\httpx\_client.py", line 1719, in _send_single_request
    response = await transport.handle_async_request(request)
               ^^^^^^^^^^^^^^^^^^^^^^^^^^^^^^^^^^^^^^^^^^^^^
  File "C:\Users\F12$\AppData\Local\Programs\Python\Python311\Lib\site-packages\httpx\_transports\default.py", line 365, in handle_async_request
    with map_httpcore_exceptions():
  File "C:\Users\F12$\AppData\Local\Programs\Python\Python311\Lib\contextlib.py", line 158, in __exit__
    self.gen.throw(typ, value, traceback)
  File "C:\Users\F12$\AppData\Local\Programs\Python\Python311\Lib\site-packages\httpx\_transports\default.py", line 83, in map_httpcore_exceptions
    raise mapped_exc(message) from exc
httpx.ConnectError: [Errno 11001] getaddrinfo failed

The above exception was the direct cause of the following exception:

Traceback (most recent call last):
  File "C:\Users\F12$\AppData\Local\Programs\Python\Python311\Lib\site-packages\telegram\ext\_updater.py", line 688, in _network_loop_retry
    if not await action_cb():
           ^^^^^^^^^^^^^^^^^
  File "C:\Users\F12$\AppData\Local\Programs\Python\Python311\Lib\site-packages\telegram\ext\_updater.py", line 384, in polling_action_cb
    raise exc
  File "C:\Users\F12$\AppData\Local\Programs\Python\Python311\Lib\site-packages\telegram\ext\_updater.py", line 373, in polling_action_cb
    updates = await self.bot.get_updates(
              ^^^^^^^^^^^^^^^^^^^^^^^^^^^
  File "C:\Users\F12$\AppData\Local\Programs\Python\Python311\Lib\site-packages\telegram\ext\_extbot.py", line 558, in get_updates
    updates = await super().get_updates(
              ^^^^^^^^^^^^^^^^^^^^^^^^^^
  File "C:\Users\F12$\AppData\Local\Programs\Python\Python311\Lib\site-packages\telegram\_bot.py", line 525, in decorator
    result = await func(self, *args, **kwargs)  # skipcq: PYL-E1102
             ^^^^^^^^^^^^^^^^^^^^^^^^^^^^^^^^^
  File "C:\Users\F12$\AppData\Local\Programs\Python\Python311\Lib\site-packages\telegram\_bot.py", line 3584, in get_updates
    await self._post(
  File "C:\Users\F12$\AppData\Local\Programs\Python\Python311\Lib\site-packages\telegram\_bot.py", line 613, in _post
    return await self._do_post(
           ^^^^^^^^^^^^^^^^^^^^
  File "C:\Users\F12$\AppData\Local\Programs\Python\Python311\Lib\site-packages\telegram\ext\_extbot.py", line 340, in _do_post
    return await super()._do_post(
           ^^^^^^^^^^^^^^^^^^^^^^^
  File "C:\Users\F12$\AppData\Local\Programs\Python\Python311\Lib\site-packages\telegram\_bot.py", line 641, in _do_post
    return await request.post(
           ^^^^^^^^^^^^^^^^^^^
  File "C:\Users\F12$\AppData\Local\Programs\Python\Python311\Lib\site-packages\telegram\request\_baserequest.py", line 200, in post
    result = await self._request_wrapper(
             ^^^^^^^^^^^^^^^^^^^^^^^^^^^^
  File "C:\Users\F12$\AppData\Local\Programs\Python\Python311\Lib\site-packages\telegram\request\_baserequest.py", line 340, in _request_wrapper
    raise exc
  File "C:\Users\F12$\AppData\Local\Programs\Python\Python311\Lib\site-packages\telegram\request\_baserequest.py", line 330, in _request_wrapper
    code, payload = await self.do_request(
                    ^^^^^^^^^^^^^^^^^^^^^^
  File "C:\Users\F12$\AppData\Local\Programs\Python\Python311\Lib\site-packages\telegram\request\_httpxrequest.py", line 292, in do_request
    raise NetworkError(f"httpx.{err.__class__.__name__}: {err}") from err
telegram.error.NetworkError: httpx.ConnectError: [Errno 11001] getaddrinfo failed
2025-06-24 18:58:13 - telegram.ext.Updater - ERROR - Error while getting Updates: httpx.ConnectError: [Errno 11001] getaddrinfo failed
2025-06-24 18:58:13 - telegram.ext.Application - ERROR - No error handlers are registered, logging exception.
Traceback (most recent call last):
  File "C:\Users\F12$\AppData\Local\Programs\Python\Python311\Lib\site-packages\httpx\_transports\default.py", line 66, in map_httpcore_exceptions
    yield
  File "C:\Users\F12$\AppData\Local\Programs\Python\Python311\Lib\site-packages\httpx\_transports\default.py", line 366, in handle_async_request
    resp = await self._pool.handle_async_request(req)
           ^^^^^^^^^^^^^^^^^^^^^^^^^^^^^^^^^^^^^^^^^^
  File "C:\Users\F12$\AppData\Local\Programs\Python\Python311\Lib\site-packages\httpcore\_async\connection_pool.py", line 256, in handle_async_request
    raise exc from None
  File "C:\Users\F12$\AppData\Local\Programs\Python\Python311\Lib\site-packages\httpcore\_async\connection_pool.py", line 236, in handle_async_request
    response = await connection.handle_async_request(
               ^^^^^^^^^^^^^^^^^^^^^^^^^^^^^^^^^^^^^^
  File "C:\Users\F12$\AppData\Local\Programs\Python\Python311\Lib\site-packages\httpcore\_async\connection.py", line 101, in handle_async_request
    raise exc
  File "C:\Users\F12$\AppData\Local\Programs\Python\Python311\Lib\site-packages\httpcore\_async\connection.py", line 78, in handle_async_request
    stream = await self._connect(request)
             ^^^^^^^^^^^^^^^^^^^^^^^^^^^^
  File "C:\Users\F12$\AppData\Local\Programs\Python\Python311\Lib\site-packages\httpcore\_async\connection.py", line 124, in _connect
    stream = await self._network_backend.connect_tcp(**kwargs)
             ^^^^^^^^^^^^^^^^^^^^^^^^^^^^^^^^^^^^^^^^^^^^^^^^^
  File "C:\Users\F12$\AppData\Local\Programs\Python\Python311\Lib\site-packages\httpcore\_backends\auto.py", line 31, in connect_tcp
    return await self._backend.connect_tcp(
           ^^^^^^^^^^^^^^^^^^^^^^^^^^^^^^^^
  File "C:\Users\F12$\AppData\Local\Programs\Python\Python311\Lib\site-packages\httpcore\_backends\anyio.py", line 113, in connect_tcp
    with map_exceptions(exc_map):
  File "C:\Users\F12$\AppData\Local\Programs\Python\Python311\Lib\contextlib.py", line 158, in __exit__
    self.gen.throw(typ, value, traceback)
  File "C:\Users\F12$\AppData\Local\Programs\Python\Python311\Lib\site-packages\httpcore\_exceptions.py", line 14, in map_exceptions
    raise to_exc(exc) from exc
httpcore.ConnectError: [Errno 11001] getaddrinfo failed

The above exception was the direct cause of the following exception:

Traceback (most recent call last):
  File "C:\Users\F12$\AppData\Local\Programs\Python\Python311\Lib\site-packages\telegram\request\_httpxrequest.py", line 268, in do_request
    res = await self._client.request(
          ^^^^^^^^^^^^^^^^^^^^^^^^^^^
  File "C:\Users\F12$\AppData\Local\Programs\Python\Python311\Lib\site-packages\httpx\_client.py", line 1530, in request
    return await self.send(request, auth=auth, follow_redirects=follow_redirects)
           ^^^^^^^^^^^^^^^^^^^^^^^^^^^^^^^^^^^^^^^^^^^^^^^^^^^^^^^^^^^^^^^^^^^^^^
  File "C:\Users\F12$\AppData\Local\Programs\Python\Python311\Lib\site-packages\httpx\_client.py", line 1617, in send
    response = await self._send_handling_auth(
               ^^^^^^^^^^^^^^^^^^^^^^^^^^^^^^^
  File "C:\Users\F12$\AppData\Local\Programs\Python\Python311\Lib\site-packages\httpx\_client.py", line 1645, in _send_handling_auth
    response = await self._send_handling_redirects(
               ^^^^^^^^^^^^^^^^^^^^^^^^^^^^^^^^^^^^
  File "C:\Users\F12$\AppData\Local\Programs\Python\Python311\Lib\site-packages\httpx\_client.py", line 1682, in _send_handling_redirects
    response = await self._send_single_request(request)
               ^^^^^^^^^^^^^^^^^^^^^^^^^^^^^^^^^^^^^^^^
  File "C:\Users\F12$\AppData\Local\Programs\Python\Python311\Lib\site-packages\httpx\_client.py", line 1719, in _send_single_request
    response = await transport.handle_async_request(request)
               ^^^^^^^^^^^^^^^^^^^^^^^^^^^^^^^^^^^^^^^^^^^^^
  File "C:\Users\F12$\AppData\Local\Programs\Python\Python311\Lib\site-packages\httpx\_transports\default.py", line 365, in handle_async_request
    with map_httpcore_exceptions():
  File "C:\Users\F12$\AppData\Local\Programs\Python\Python311\Lib\contextlib.py", line 158, in __exit__
    self.gen.throw(typ, value, traceback)
  File "C:\Users\F12$\AppData\Local\Programs\Python\Python311\Lib\site-packages\httpx\_transports\default.py", line 83, in map_httpcore_exceptions
    raise mapped_exc(message) from exc
httpx.ConnectError: [Errno 11001] getaddrinfo failed

The above exception was the direct cause of the following exception:

Traceback (most recent call last):
  File "C:\Users\F12$\AppData\Local\Programs\Python\Python311\Lib\site-packages\telegram\ext\_updater.py", line 688, in _network_loop_retry
    if not await action_cb():
           ^^^^^^^^^^^^^^^^^
  File "C:\Users\F12$\AppData\Local\Programs\Python\Python311\Lib\site-packages\telegram\ext\_updater.py", line 384, in polling_action_cb
    raise exc
  File "C:\Users\F12$\AppData\Local\Programs\Python\Python311\Lib\site-packages\telegram\ext\_updater.py", line 373, in polling_action_cb
    updates = await self.bot.get_updates(
              ^^^^^^^^^^^^^^^^^^^^^^^^^^^
  File "C:\Users\F12$\AppData\Local\Programs\Python\Python311\Lib\site-packages\telegram\ext\_extbot.py", line 558, in get_updates
    updates = await super().get_updates(
              ^^^^^^^^^^^^^^^^^^^^^^^^^^
  File "C:\Users\F12$\AppData\Local\Programs\Python\Python311\Lib\site-packages\telegram\_bot.py", line 525, in decorator
    result = await func(self, *args, **kwargs)  # skipcq: PYL-E1102
             ^^^^^^^^^^^^^^^^^^^^^^^^^^^^^^^^^
  File "C:\Users\F12$\AppData\Local\Programs\Python\Python311\Lib\site-packages\telegram\_bot.py", line 3584, in get_updates
    await self._post(
  File "C:\Users\F12$\AppData\Local\Programs\Python\Python311\Lib\site-packages\telegram\_bot.py", line 613, in _post
    return await self._do_post(
           ^^^^^^^^^^^^^^^^^^^^
  File "C:\Users\F12$\AppData\Local\Programs\Python\Python311\Lib\site-packages\telegram\ext\_extbot.py", line 340, in _do_post
    return await super()._do_post(
           ^^^^^^^^^^^^^^^^^^^^^^^
  File "C:\Users\F12$\AppData\Local\Programs\Python\Python311\Lib\site-packages\telegram\_bot.py", line 641, in _do_post
    return await request.post(
           ^^^^^^^^^^^^^^^^^^^
  File "C:\Users\F12$\AppData\Local\Programs\Python\Python311\Lib\site-packages\telegram\request\_baserequest.py", line 200, in post
    result = await self._request_wrapper(
             ^^^^^^^^^^^^^^^^^^^^^^^^^^^^
  File "C:\Users\F12$\AppData\Local\Programs\Python\Python311\Lib\site-packages\telegram\request\_baserequest.py", line 340, in _request_wrapper
    raise exc
  File "C:\Users\F12$\AppData\Local\Programs\Python\Python311\Lib\site-packages\telegram\request\_baserequest.py", line 330, in _request_wrapper
    code, payload = await self.do_request(
                    ^^^^^^^^^^^^^^^^^^^^^^
  File "C:\Users\F12$\AppData\Local\Programs\Python\Python311\Lib\site-packages\telegram\request\_httpxrequest.py", line 292, in do_request
    raise NetworkError(f"httpx.{err.__class__.__name__}: {err}") from err
telegram.error.NetworkError: httpx.ConnectError: [Errno 11001] getaddrinfo failed
2025-06-24 18:58:15 - telegram.ext.Updater - ERROR - Error while getting Updates: httpx.ConnectError: [Errno 11001] getaddrinfo failed
2025-06-24 18:58:15 - telegram.ext.Application - ERROR - No error handlers are registered, logging exception.
Traceback (most recent call last):
  File "C:\Users\F12$\AppData\Local\Programs\Python\Python311\Lib\site-packages\httpx\_transports\default.py", line 66, in map_httpcore_exceptions
    yield
  File "C:\Users\F12$\AppData\Local\Programs\Python\Python311\Lib\site-packages\httpx\_transports\default.py", line 366, in handle_async_request
    resp = await self._pool.handle_async_request(req)
           ^^^^^^^^^^^^^^^^^^^^^^^^^^^^^^^^^^^^^^^^^^
  File "C:\Users\F12$\AppData\Local\Programs\Python\Python311\Lib\site-packages\httpcore\_async\connection_pool.py", line 256, in handle_async_request
    raise exc from None
  File "C:\Users\F12$\AppData\Local\Programs\Python\Python311\Lib\site-packages\httpcore\_async\connection_pool.py", line 236, in handle_async_request
    response = await connection.handle_async_request(
               ^^^^^^^^^^^^^^^^^^^^^^^^^^^^^^^^^^^^^^
  File "C:\Users\F12$\AppData\Local\Programs\Python\Python311\Lib\site-packages\httpcore\_async\connection.py", line 101, in handle_async_request
    raise exc
  File "C:\Users\F12$\AppData\Local\Programs\Python\Python311\Lib\site-packages\httpcore\_async\connection.py", line 78, in handle_async_request
    stream = await self._connect(request)
             ^^^^^^^^^^^^^^^^^^^^^^^^^^^^
  File "C:\Users\F12$\AppData\Local\Programs\Python\Python311\Lib\site-packages\httpcore\_async\connection.py", line 124, in _connect
    stream = await self._network_backend.connect_tcp(**kwargs)
             ^^^^^^^^^^^^^^^^^^^^^^^^^^^^^^^^^^^^^^^^^^^^^^^^^
  File "C:\Users\F12$\AppData\Local\Programs\Python\Python311\Lib\site-packages\httpcore\_backends\auto.py", line 31, in connect_tcp
    return await self._backend.connect_tcp(
           ^^^^^^^^^^^^^^^^^^^^^^^^^^^^^^^^
  File "C:\Users\F12$\AppData\Local\Programs\Python\Python311\Lib\site-packages\httpcore\_backends\anyio.py", line 113, in connect_tcp
    with map_exceptions(exc_map):
  File "C:\Users\F12$\AppData\Local\Programs\Python\Python311\Lib\contextlib.py", line 158, in __exit__
    self.gen.throw(typ, value, traceback)
  File "C:\Users\F12$\AppData\Local\Programs\Python\Python311\Lib\site-packages\httpcore\_exceptions.py", line 14, in map_exceptions
    raise to_exc(exc) from exc
httpcore.ConnectError: [Errno 11001] getaddrinfo failed

The above exception was the direct cause of the following exception:

Traceback (most recent call last):
  File "C:\Users\F12$\AppData\Local\Programs\Python\Python311\Lib\site-packages\telegram\request\_httpxrequest.py", line 268, in do_request
    res = await self._client.request(
          ^^^^^^^^^^^^^^^^^^^^^^^^^^^
  File "C:\Users\F12$\AppData\Local\Programs\Python\Python311\Lib\site-packages\httpx\_client.py", line 1530, in request
    return await self.send(request, auth=auth, follow_redirects=follow_redirects)
           ^^^^^^^^^^^^^^^^^^^^^^^^^^^^^^^^^^^^^^^^^^^^^^^^^^^^^^^^^^^^^^^^^^^^^^
  File "C:\Users\F12$\AppData\Local\Programs\Python\Python311\Lib\site-packages\httpx\_client.py", line 1617, in send
    response = await self._send_handling_auth(
               ^^^^^^^^^^^^^^^^^^^^^^^^^^^^^^^
  File "C:\Users\F12$\AppData\Local\Programs\Python\Python311\Lib\site-packages\httpx\_client.py", line 1645, in _send_handling_auth
    response = await self._send_handling_redirects(
               ^^^^^^^^^^^^^^^^^^^^^^^^^^^^^^^^^^^^
  File "C:\Users\F12$\AppData\Local\Programs\Python\Python311\Lib\site-packages\httpx\_client.py", line 1682, in _send_handling_redirects
    response = await self._send_single_request(request)
               ^^^^^^^^^^^^^^^^^^^^^^^^^^^^^^^^^^^^^^^^
  File "C:\Users\F12$\AppData\Local\Programs\Python\Python311\Lib\site-packages\httpx\_client.py", line 1719, in _send_single_request
    response = await transport.handle_async_request(request)
               ^^^^^^^^^^^^^^^^^^^^^^^^^^^^^^^^^^^^^^^^^^^^^
  File "C:\Users\F12$\AppData\Local\Programs\Python\Python311\Lib\site-packages\httpx\_transports\default.py", line 365, in handle_async_request
    with map_httpcore_exceptions():
  File "C:\Users\F12$\AppData\Local\Programs\Python\Python311\Lib\contextlib.py", line 158, in __exit__
    self.gen.throw(typ, value, traceback)
  File "C:\Users\F12$\AppData\Local\Programs\Python\Python311\Lib\site-packages\httpx\_transports\default.py", line 83, in map_httpcore_exceptions
    raise mapped_exc(message) from exc
httpx.ConnectError: [Errno 11001] getaddrinfo failed

The above exception was the direct cause of the following exception:

Traceback (most recent call last):
  File "C:\Users\F12$\AppData\Local\Programs\Python\Python311\Lib\site-packages\telegram\ext\_updater.py", line 688, in _network_loop_retry
    if not await action_cb():
           ^^^^^^^^^^^^^^^^^
  File "C:\Users\F12$\AppData\Local\Programs\Python\Python311\Lib\site-packages\telegram\ext\_updater.py", line 384, in polling_action_cb
    raise exc
  File "C:\Users\F12$\AppData\Local\Programs\Python\Python311\Lib\site-packages\telegram\ext\_updater.py", line 373, in polling_action_cb
    updates = await self.bot.get_updates(
              ^^^^^^^^^^^^^^^^^^^^^^^^^^^
  File "C:\Users\F12$\AppData\Local\Programs\Python\Python311\Lib\site-packages\telegram\ext\_extbot.py", line 558, in get_updates
    updates = await super().get_updates(
              ^^^^^^^^^^^^^^^^^^^^^^^^^^
  File "C:\Users\F12$\AppData\Local\Programs\Python\Python311\Lib\site-packages\telegram\_bot.py", line 525, in decorator
    result = await func(self, *args, **kwargs)  # skipcq: PYL-E1102
             ^^^^^^^^^^^^^^^^^^^^^^^^^^^^^^^^^
  File "C:\Users\F12$\AppData\Local\Programs\Python\Python311\Lib\site-packages\telegram\_bot.py", line 3584, in get_updates
    await self._post(
  File "C:\Users\F12$\AppData\Local\Programs\Python\Python311\Lib\site-packages\telegram\_bot.py", line 613, in _post
    return await self._do_post(
           ^^^^^^^^^^^^^^^^^^^^
  File "C:\Users\F12$\AppData\Local\Programs\Python\Python311\Lib\site-packages\telegram\ext\_extbot.py", line 340, in _do_post
    return await super()._do_post(
           ^^^^^^^^^^^^^^^^^^^^^^^
  File "C:\Users\F12$\AppData\Local\Programs\Python\Python311\Lib\site-packages\telegram\_bot.py", line 641, in _do_post
    return await request.post(
           ^^^^^^^^^^^^^^^^^^^
  File "C:\Users\F12$\AppData\Local\Programs\Python\Python311\Lib\site-packages\telegram\request\_baserequest.py", line 200, in post
    result = await self._request_wrapper(
             ^^^^^^^^^^^^^^^^^^^^^^^^^^^^
  File "C:\Users\F12$\AppData\Local\Programs\Python\Python311\Lib\site-packages\telegram\request\_baserequest.py", line 340, in _request_wrapper
    raise exc
  File "C:\Users\F12$\AppData\Local\Programs\Python\Python311\Lib\site-packages\telegram\request\_baserequest.py", line 330, in _request_wrapper
    code, payload = await self.do_request(
                    ^^^^^^^^^^^^^^^^^^^^^^
  File "C:\Users\F12$\AppData\Local\Programs\Python\Python311\Lib\site-packages\telegram\request\_httpxrequest.py", line 292, in do_request
    raise NetworkError(f"httpx.{err.__class__.__name__}: {err}") from err
telegram.error.NetworkError: httpx.ConnectError: [Errno 11001] getaddrinfo failed
2025-06-24 18:58:17 - telegram.ext.Updater - ERROR - Error while getting Updates: httpx.ConnectError: [Errno 11001] getaddrinfo failed
2025-06-24 18:58:17 - telegram.ext.Application - ERROR - No error handlers are registered, logging exception.
Traceback (most recent call last):
  File "C:\Users\F12$\AppData\Local\Programs\Python\Python311\Lib\site-packages\httpx\_transports\default.py", line 66, in map_httpcore_exceptions
    yield
  File "C:\Users\F12$\AppData\Local\Programs\Python\Python311\Lib\site-packages\httpx\_transports\default.py", line 366, in handle_async_request
    resp = await self._pool.handle_async_request(req)
           ^^^^^^^^^^^^^^^^^^^^^^^^^^^^^^^^^^^^^^^^^^
  File "C:\Users\F12$\AppData\Local\Programs\Python\Python311\Lib\site-packages\httpcore\_async\connection_pool.py", line 256, in handle_async_request
    raise exc from None
  File "C:\Users\F12$\AppData\Local\Programs\Python\Python311\Lib\site-packages\httpcore\_async\connection_pool.py", line 236, in handle_async_request
    response = await connection.handle_async_request(
               ^^^^^^^^^^^^^^^^^^^^^^^^^^^^^^^^^^^^^^
  File "C:\Users\F12$\AppData\Local\Programs\Python\Python311\Lib\site-packages\httpcore\_async\connection.py", line 101, in handle_async_request
    raise exc
  File "C:\Users\F12$\AppData\Local\Programs\Python\Python311\Lib\site-packages\httpcore\_async\connection.py", line 78, in handle_async_request
    stream = await self._connect(request)
             ^^^^^^^^^^^^^^^^^^^^^^^^^^^^
  File "C:\Users\F12$\AppData\Local\Programs\Python\Python311\Lib\site-packages\httpcore\_async\connection.py", line 124, in _connect
    stream = await self._network_backend.connect_tcp(**kwargs)
             ^^^^^^^^^^^^^^^^^^^^^^^^^^^^^^^^^^^^^^^^^^^^^^^^^
  File "C:\Users\F12$\AppData\Local\Programs\Python\Python311\Lib\site-packages\httpcore\_backends\auto.py", line 31, in connect_tcp
    return await self._backend.connect_tcp(
           ^^^^^^^^^^^^^^^^^^^^^^^^^^^^^^^^
  File "C:\Users\F12$\AppData\Local\Programs\Python\Python311\Lib\site-packages\httpcore\_backends\anyio.py", line 113, in connect_tcp
    with map_exceptions(exc_map):
  File "C:\Users\F12$\AppData\Local\Programs\Python\Python311\Lib\contextlib.py", line 158, in __exit__
    self.gen.throw(typ, value, traceback)
  File "C:\Users\F12$\AppData\Local\Programs\Python\Python311\Lib\site-packages\httpcore\_exceptions.py", line 14, in map_exceptions
    raise to_exc(exc) from exc
httpcore.ConnectError: [Errno 11001] getaddrinfo failed

The above exception was the direct cause of the following exception:

Traceback (most recent call last):
  File "C:\Users\F12$\AppData\Local\Programs\Python\Python311\Lib\site-packages\telegram\request\_httpxrequest.py", line 268, in do_request
    res = await self._client.request(
          ^^^^^^^^^^^^^^^^^^^^^^^^^^^
  File "C:\Users\F12$\AppData\Local\Programs\Python\Python311\Lib\site-packages\httpx\_client.py", line 1530, in request
    return await self.send(request, auth=auth, follow_redirects=follow_redirects)
           ^^^^^^^^^^^^^^^^^^^^^^^^^^^^^^^^^^^^^^^^^^^^^^^^^^^^^^^^^^^^^^^^^^^^^^
  File "C:\Users\F12$\AppData\Local\Programs\Python\Python311\Lib\site-packages\httpx\_client.py", line 1617, in send
    response = await self._send_handling_auth(
               ^^^^^^^^^^^^^^^^^^^^^^^^^^^^^^^
  File "C:\Users\F12$\AppData\Local\Programs\Python\Python311\Lib\site-packages\httpx\_client.py", line 1645, in _send_handling_auth
    response = await self._send_handling_redirects(
               ^^^^^^^^^^^^^^^^^^^^^^^^^^^^^^^^^^^^
  File "C:\Users\F12$\AppData\Local\Programs\Python\Python311\Lib\site-packages\httpx\_client.py", line 1682, in _send_handling_redirects
    response = await self._send_single_request(request)
               ^^^^^^^^^^^^^^^^^^^^^^^^^^^^^^^^^^^^^^^^
  File "C:\Users\F12$\AppData\Local\Programs\Python\Python311\Lib\site-packages\httpx\_client.py", line 1719, in _send_single_request
    response = await transport.handle_async_request(request)
               ^^^^^^^^^^^^^^^^^^^^^^^^^^^^^^^^^^^^^^^^^^^^^
  File "C:\Users\F12$\AppData\Local\Programs\Python\Python311\Lib\site-packages\httpx\_transports\default.py", line 365, in handle_async_request
    with map_httpcore_exceptions():
  File "C:\Users\F12$\AppData\Local\Programs\Python\Python311\Lib\contextlib.py", line 158, in __exit__
    self.gen.throw(typ, value, traceback)
  File "C:\Users\F12$\AppData\Local\Programs\Python\Python311\Lib\site-packages\httpx\_transports\default.py", line 83, in map_httpcore_exceptions
    raise mapped_exc(message) from exc
httpx.ConnectError: [Errno 11001] getaddrinfo failed

The above exception was the direct cause of the following exception:

Traceback (most recent call last):
  File "C:\Users\F12$\AppData\Local\Programs\Python\Python311\Lib\site-packages\telegram\ext\_updater.py", line 688, in _network_loop_retry
    if not await action_cb():
           ^^^^^^^^^^^^^^^^^
  File "C:\Users\F12$\AppData\Local\Programs\Python\Python311\Lib\site-packages\telegram\ext\_updater.py", line 384, in polling_action_cb
    raise exc
  File "C:\Users\F12$\AppData\Local\Programs\Python\Python311\Lib\site-packages\telegram\ext\_updater.py", line 373, in polling_action_cb
    updates = await self.bot.get_updates(
              ^^^^^^^^^^^^^^^^^^^^^^^^^^^
  File "C:\Users\F12$\AppData\Local\Programs\Python\Python311\Lib\site-packages\telegram\ext\_extbot.py", line 558, in get_updates
    updates = await super().get_updates(
              ^^^^^^^^^^^^^^^^^^^^^^^^^^
  File "C:\Users\F12$\AppData\Local\Programs\Python\Python311\Lib\site-packages\telegram\_bot.py", line 525, in decorator
    result = await func(self, *args, **kwargs)  # skipcq: PYL-E1102
             ^^^^^^^^^^^^^^^^^^^^^^^^^^^^^^^^^
  File "C:\Users\F12$\AppData\Local\Programs\Python\Python311\Lib\site-packages\telegram\_bot.py", line 3584, in get_updates
    await self._post(
  File "C:\Users\F12$\AppData\Local\Programs\Python\Python311\Lib\site-packages\telegram\_bot.py", line 613, in _post
    return await self._do_post(
           ^^^^^^^^^^^^^^^^^^^^
  File "C:\Users\F12$\AppData\Local\Programs\Python\Python311\Lib\site-packages\telegram\ext\_extbot.py", line 340, in _do_post
    return await super()._do_post(
           ^^^^^^^^^^^^^^^^^^^^^^^
  File "C:\Users\F12$\AppData\Local\Programs\Python\Python311\Lib\site-packages\telegram\_bot.py", line 641, in _do_post
    return await request.post(
           ^^^^^^^^^^^^^^^^^^^
  File "C:\Users\F12$\AppData\Local\Programs\Python\Python311\Lib\site-packages\telegram\request\_baserequest.py", line 200, in post
    result = await self._request_wrapper(
             ^^^^^^^^^^^^^^^^^^^^^^^^^^^^
  File "C:\Users\F12$\AppData\Local\Programs\Python\Python311\Lib\site-packages\telegram\request\_baserequest.py", line 340, in _request_wrapper
    raise exc
  File "C:\Users\F12$\AppData\Local\Programs\Python\Python311\Lib\site-packages\telegram\request\_baserequest.py", line 330, in _request_wrapper
    code, payload = await self.do_request(
                    ^^^^^^^^^^^^^^^^^^^^^^
  File "C:\Users\F12$\AppData\Local\Programs\Python\Python311\Lib\site-packages\telegram\request\_httpxrequest.py", line 292, in do_request
    raise NetworkError(f"httpx.{err.__class__.__name__}: {err}") from err
telegram.error.NetworkError: httpx.ConnectError: [Errno 11001] getaddrinfo failed
2025-06-24 18:58:20 - telegram.ext.Updater - ERROR - Error while getting Updates: httpx.ConnectError: [Errno 11001] getaddrinfo failed
2025-06-24 18:58:20 - telegram.ext.Application - ERROR - No error handlers are registered, logging exception.
Traceback (most recent call last):
  File "C:\Users\F12$\AppData\Local\Programs\Python\Python311\Lib\site-packages\httpx\_transports\default.py", line 66, in map_httpcore_exceptions
    yield
  File "C:\Users\F12$\AppData\Local\Programs\Python\Python311\Lib\site-packages\httpx\_transports\default.py", line 366, in handle_async_request
    resp = await self._pool.handle_async_request(req)
           ^^^^^^^^^^^^^^^^^^^^^^^^^^^^^^^^^^^^^^^^^^
  File "C:\Users\F12$\AppData\Local\Programs\Python\Python311\Lib\site-packages\httpcore\_async\connection_pool.py", line 256, in handle_async_request
    raise exc from None
  File "C:\Users\F12$\AppData\Local\Programs\Python\Python311\Lib\site-packages\httpcore\_async\connection_pool.py", line 236, in handle_async_request
    response = await connection.handle_async_request(
               ^^^^^^^^^^^^^^^^^^^^^^^^^^^^^^^^^^^^^^
  File "C:\Users\F12$\AppData\Local\Programs\Python\Python311\Lib\site-packages\httpcore\_async\connection.py", line 101, in handle_async_request
    raise exc
  File "C:\Users\F12$\AppData\Local\Programs\Python\Python311\Lib\site-packages\httpcore\_async\connection.py", line 78, in handle_async_request
    stream = await self._connect(request)
             ^^^^^^^^^^^^^^^^^^^^^^^^^^^^
  File "C:\Users\F12$\AppData\Local\Programs\Python\Python311\Lib\site-packages\httpcore\_async\connection.py", line 124, in _connect
    stream = await self._network_backend.connect_tcp(**kwargs)
             ^^^^^^^^^^^^^^^^^^^^^^^^^^^^^^^^^^^^^^^^^^^^^^^^^
  File "C:\Users\F12$\AppData\Local\Programs\Python\Python311\Lib\site-packages\httpcore\_backends\auto.py", line 31, in connect_tcp
    return await self._backend.connect_tcp(
           ^^^^^^^^^^^^^^^^^^^^^^^^^^^^^^^^
  File "C:\Users\F12$\AppData\Local\Programs\Python\Python311\Lib\site-packages\httpcore\_backends\anyio.py", line 113, in connect_tcp
    with map_exceptions(exc_map):
  File "C:\Users\F12$\AppData\Local\Programs\Python\Python311\Lib\contextlib.py", line 158, in __exit__
    self.gen.throw(typ, value, traceback)
  File "C:\Users\F12$\AppData\Local\Programs\Python\Python311\Lib\site-packages\httpcore\_exceptions.py", line 14, in map_exceptions
    raise to_exc(exc) from exc
httpcore.ConnectError: [Errno 11001] getaddrinfo failed

The above exception was the direct cause of the following exception:

Traceback (most recent call last):
  File "C:\Users\F12$\AppData\Local\Programs\Python\Python311\Lib\site-packages\telegram\request\_httpxrequest.py", line 268, in do_request
    res = await self._client.request(
          ^^^^^^^^^^^^^^^^^^^^^^^^^^^
  File "C:\Users\F12$\AppData\Local\Programs\Python\Python311\Lib\site-packages\httpx\_client.py", line 1530, in request
    return await self.send(request, auth=auth, follow_redirects=follow_redirects)
           ^^^^^^^^^^^^^^^^^^^^^^^^^^^^^^^^^^^^^^^^^^^^^^^^^^^^^^^^^^^^^^^^^^^^^^
  File "C:\Users\F12$\AppData\Local\Programs\Python\Python311\Lib\site-packages\httpx\_client.py", line 1617, in send
    response = await self._send_handling_auth(
               ^^^^^^^^^^^^^^^^^^^^^^^^^^^^^^^
  File "C:\Users\F12$\AppData\Local\Programs\Python\Python311\Lib\site-packages\httpx\_client.py", line 1645, in _send_handling_auth
    response = await self._send_handling_redirects(
               ^^^^^^^^^^^^^^^^^^^^^^^^^^^^^^^^^^^^
  File "C:\Users\F12$\AppData\Local\Programs\Python\Python311\Lib\site-packages\httpx\_client.py", line 1682, in _send_handling_redirects
    response = await self._send_single_request(request)
               ^^^^^^^^^^^^^^^^^^^^^^^^^^^^^^^^^^^^^^^^
  File "C:\Users\F12$\AppData\Local\Programs\Python\Python311\Lib\site-packages\httpx\_client.py", line 1719, in _send_single_request
    response = await transport.handle_async_request(request)
               ^^^^^^^^^^^^^^^^^^^^^^^^^^^^^^^^^^^^^^^^^^^^^
  File "C:\Users\F12$\AppData\Local\Programs\Python\Python311\Lib\site-packages\httpx\_transports\default.py", line 365, in handle_async_request
    with map_httpcore_exceptions():
  File "C:\Users\F12$\AppData\Local\Programs\Python\Python311\Lib\contextlib.py", line 158, in __exit__
    self.gen.throw(typ, value, traceback)
  File "C:\Users\F12$\AppData\Local\Programs\Python\Python311\Lib\site-packages\httpx\_transports\default.py", line 83, in map_httpcore_exceptions
    raise mapped_exc(message) from exc
httpx.ConnectError: [Errno 11001] getaddrinfo failed

The above exception was the direct cause of the following exception:

Traceback (most recent call last):
  File "C:\Users\F12$\AppData\Local\Programs\Python\Python311\Lib\site-packages\telegram\ext\_updater.py", line 688, in _network_loop_retry
    if not await action_cb():
           ^^^^^^^^^^^^^^^^^
  File "C:\Users\F12$\AppData\Local\Programs\Python\Python311\Lib\site-packages\telegram\ext\_updater.py", line 384, in polling_action_cb
    raise exc
  File "C:\Users\F12$\AppData\Local\Programs\Python\Python311\Lib\site-packages\telegram\ext\_updater.py", line 373, in polling_action_cb
    updates = await self.bot.get_updates(
              ^^^^^^^^^^^^^^^^^^^^^^^^^^^
  File "C:\Users\F12$\AppData\Local\Programs\Python\Python311\Lib\site-packages\telegram\ext\_extbot.py", line 558, in get_updates
    updates = await super().get_updates(
              ^^^^^^^^^^^^^^^^^^^^^^^^^^
  File "C:\Users\F12$\AppData\Local\Programs\Python\Python311\Lib\site-packages\telegram\_bot.py", line 525, in decorator
    result = await func(self, *args, **kwargs)  # skipcq: PYL-E1102
             ^^^^^^^^^^^^^^^^^^^^^^^^^^^^^^^^^
  File "C:\Users\F12$\AppData\Local\Programs\Python\Python311\Lib\site-packages\telegram\_bot.py", line 3584, in get_updates
    await self._post(
  File "C:\Users\F12$\AppData\Local\Programs\Python\Python311\Lib\site-packages\telegram\_bot.py", line 613, in _post
    return await self._do_post(
           ^^^^^^^^^^^^^^^^^^^^
  File "C:\Users\F12$\AppData\Local\Programs\Python\Python311\Lib\site-packages\telegram\ext\_extbot.py", line 340, in _do_post
    return await super()._do_post(
           ^^^^^^^^^^^^^^^^^^^^^^^
  File "C:\Users\F12$\AppData\Local\Programs\Python\Python311\Lib\site-packages\telegram\_bot.py", line 641, in _do_post
    return await request.post(
           ^^^^^^^^^^^^^^^^^^^
  File "C:\Users\F12$\AppData\Local\Programs\Python\Python311\Lib\site-packages\telegram\request\_baserequest.py", line 200, in post
    result = await self._request_wrapper(
             ^^^^^^^^^^^^^^^^^^^^^^^^^^^^
  File "C:\Users\F12$\AppData\Local\Programs\Python\Python311\Lib\site-packages\telegram\request\_baserequest.py", line 340, in _request_wrapper
    raise exc
  File "C:\Users\F12$\AppData\Local\Programs\Python\Python311\Lib\site-packages\telegram\request\_baserequest.py", line 330, in _request_wrapper
    code, payload = await self.do_request(
                    ^^^^^^^^^^^^^^^^^^^^^^
  File "C:\Users\F12$\AppData\Local\Programs\Python\Python311\Lib\site-packages\telegram\request\_httpxrequest.py", line 292, in do_request
    raise NetworkError(f"httpx.{err.__class__.__name__}: {err}") from err
telegram.error.NetworkError: httpx.ConnectError: [Errno 11001] getaddrinfo failed
2025-06-24 18:58:26 - telegram.ext.Updater - ERROR - Error while getting Updates: httpx.ConnectError: [Errno 11001] getaddrinfo failed
2025-06-24 18:58:26 - telegram.ext.Application - ERROR - No error handlers are registered, logging exception.
Traceback (most recent call last):
  File "C:\Users\F12$\AppData\Local\Programs\Python\Python311\Lib\site-packages\httpx\_transports\default.py", line 66, in map_httpcore_exceptions
    yield
  File "C:\Users\F12$\AppData\Local\Programs\Python\Python311\Lib\site-packages\httpx\_transports\default.py", line 366, in handle_async_request
    resp = await self._pool.handle_async_request(req)
           ^^^^^^^^^^^^^^^^^^^^^^^^^^^^^^^^^^^^^^^^^^
  File "C:\Users\F12$\AppData\Local\Programs\Python\Python311\Lib\site-packages\httpcore\_async\connection_pool.py", line 256, in handle_async_request
    raise exc from None
  File "C:\Users\F12$\AppData\Local\Programs\Python\Python311\Lib\site-packages\httpcore\_async\connection_pool.py", line 236, in handle_async_request
    response = await connection.handle_async_request(
               ^^^^^^^^^^^^^^^^^^^^^^^^^^^^^^^^^^^^^^
  File "C:\Users\F12$\AppData\Local\Programs\Python\Python311\Lib\site-packages\httpcore\_async\connection.py", line 101, in handle_async_request
    raise exc
  File "C:\Users\F12$\AppData\Local\Programs\Python\Python311\Lib\site-packages\httpcore\_async\connection.py", line 78, in handle_async_request
    stream = await self._connect(request)
             ^^^^^^^^^^^^^^^^^^^^^^^^^^^^
  File "C:\Users\F12$\AppData\Local\Programs\Python\Python311\Lib\site-packages\httpcore\_async\connection.py", line 124, in _connect
    stream = await self._network_backend.connect_tcp(**kwargs)
             ^^^^^^^^^^^^^^^^^^^^^^^^^^^^^^^^^^^^^^^^^^^^^^^^^
  File "C:\Users\F12$\AppData\Local\Programs\Python\Python311\Lib\site-packages\httpcore\_backends\auto.py", line 31, in connect_tcp
    return await self._backend.connect_tcp(
           ^^^^^^^^^^^^^^^^^^^^^^^^^^^^^^^^
  File "C:\Users\F12$\AppData\Local\Programs\Python\Python311\Lib\site-packages\httpcore\_backends\anyio.py", line 113, in connect_tcp
    with map_exceptions(exc_map):
  File "C:\Users\F12$\AppData\Local\Programs\Python\Python311\Lib\contextlib.py", line 158, in __exit__
    self.gen.throw(typ, value, traceback)
  File "C:\Users\F12$\AppData\Local\Programs\Python\Python311\Lib\site-packages\httpcore\_exceptions.py", line 14, in map_exceptions
    raise to_exc(exc) from exc
httpcore.ConnectError: [Errno 11001] getaddrinfo failed

The above exception was the direct cause of the following exception:

Traceback (most recent call last):
  File "C:\Users\F12$\AppData\Local\Programs\Python\Python311\Lib\site-packages\telegram\request\_httpxrequest.py", line 268, in do_request
    res = await self._client.request(
          ^^^^^^^^^^^^^^^^^^^^^^^^^^^
  File "C:\Users\F12$\AppData\Local\Programs\Python\Python311\Lib\site-packages\httpx\_client.py", line 1530, in request
    return await self.send(request, auth=auth, follow_redirects=follow_redirects)
           ^^^^^^^^^^^^^^^^^^^^^^^^^^^^^^^^^^^^^^^^^^^^^^^^^^^^^^^^^^^^^^^^^^^^^^
  File "C:\Users\F12$\AppData\Local\Programs\Python\Python311\Lib\site-packages\httpx\_client.py", line 1617, in send
    response = await self._send_handling_auth(
               ^^^^^^^^^^^^^^^^^^^^^^^^^^^^^^^
  File "C:\Users\F12$\AppData\Local\Programs\Python\Python311\Lib\site-packages\httpx\_client.py", line 1645, in _send_handling_auth
    response = await self._send_handling_redirects(
               ^^^^^^^^^^^^^^^^^^^^^^^^^^^^^^^^^^^^
  File "C:\Users\F12$\AppData\Local\Programs\Python\Python311\Lib\site-packages\httpx\_client.py", line 1682, in _send_handling_redirects
    response = await self._send_single_request(request)
               ^^^^^^^^^^^^^^^^^^^^^^^^^^^^^^^^^^^^^^^^
  File "C:\Users\F12$\AppData\Local\Programs\Python\Python311\Lib\site-packages\httpx\_client.py", line 1719, in _send_single_request
    response = await transport.handle_async_request(request)
               ^^^^^^^^^^^^^^^^^^^^^^^^^^^^^^^^^^^^^^^^^^^^^
  File "C:\Users\F12$\AppData\Local\Programs\Python\Python311\Lib\site-packages\httpx\_transports\default.py", line 365, in handle_async_request
    with map_httpcore_exceptions():
  File "C:\Users\F12$\AppData\Local\Programs\Python\Python311\Lib\contextlib.py", line 158, in __exit__
    self.gen.throw(typ, value, traceback)
  File "C:\Users\F12$\AppData\Local\Programs\Python\Python311\Lib\site-packages\httpx\_transports\default.py", line 83, in map_httpcore_exceptions
    raise mapped_exc(message) from exc
httpx.ConnectError: [Errno 11001] getaddrinfo failed

The above exception was the direct cause of the following exception:

Traceback (most recent call last):
  File "C:\Users\F12$\AppData\Local\Programs\Python\Python311\Lib\site-packages\telegram\ext\_updater.py", line 688, in _network_loop_retry
    if not await action_cb():
           ^^^^^^^^^^^^^^^^^
  File "C:\Users\F12$\AppData\Local\Programs\Python\Python311\Lib\site-packages\telegram\ext\_updater.py", line 384, in polling_action_cb
    raise exc
  File "C:\Users\F12$\AppData\Local\Programs\Python\Python311\Lib\site-packages\telegram\ext\_updater.py", line 373, in polling_action_cb
    updates = await self.bot.get_updates(
              ^^^^^^^^^^^^^^^^^^^^^^^^^^^
  File "C:\Users\F12$\AppData\Local\Programs\Python\Python311\Lib\site-packages\telegram\ext\_extbot.py", line 558, in get_updates
    updates = await super().get_updates(
              ^^^^^^^^^^^^^^^^^^^^^^^^^^
  File "C:\Users\F12$\AppData\Local\Programs\Python\Python311\Lib\site-packages\telegram\_bot.py", line 525, in decorator
    result = await func(self, *args, **kwargs)  # skipcq: PYL-E1102
             ^^^^^^^^^^^^^^^^^^^^^^^^^^^^^^^^^
  File "C:\Users\F12$\AppData\Local\Programs\Python\Python311\Lib\site-packages\telegram\_bot.py", line 3584, in get_updates
    await self._post(
  File "C:\Users\F12$\AppData\Local\Programs\Python\Python311\Lib\site-packages\telegram\_bot.py", line 613, in _post
    return await self._do_post(
           ^^^^^^^^^^^^^^^^^^^^
  File "C:\Users\F12$\AppData\Local\Programs\Python\Python311\Lib\site-packages\telegram\ext\_extbot.py", line 340, in _do_post
    return await super()._do_post(
           ^^^^^^^^^^^^^^^^^^^^^^^
  File "C:\Users\F12$\AppData\Local\Programs\Python\Python311\Lib\site-packages\telegram\_bot.py", line 641, in _do_post
    return await request.post(
           ^^^^^^^^^^^^^^^^^^^
  File "C:\Users\F12$\AppData\Local\Programs\Python\Python311\Lib\site-packages\telegram\request\_baserequest.py", line 200, in post
    result = await self._request_wrapper(
             ^^^^^^^^^^^^^^^^^^^^^^^^^^^^
  File "C:\Users\F12$\AppData\Local\Programs\Python\Python311\Lib\site-packages\telegram\request\_baserequest.py", line 340, in _request_wrapper
    raise exc
  File "C:\Users\F12$\AppData\Local\Programs\Python\Python311\Lib\site-packages\telegram\request\_baserequest.py", line 330, in _request_wrapper
    code, payload = await self.do_request(
                    ^^^^^^^^^^^^^^^^^^^^^^
  File "C:\Users\F12$\AppData\Local\Programs\Python\Python311\Lib\site-packages\telegram\request\_httpxrequest.py", line 292, in do_request
    raise NetworkError(f"httpx.{err.__class__.__name__}: {err}") from err
telegram.error.NetworkError: httpx.ConnectError: [Errno 11001] getaddrinfo failed
2025-06-24 18:58:33 - telegram.ext.Updater - ERROR - Error while getting Updates: httpx.ConnectError: [Errno 11001] getaddrinfo failed
2025-06-24 18:58:33 - telegram.ext.Application - ERROR - No error handlers are registered, logging exception.
Traceback (most recent call last):
  File "C:\Users\F12$\AppData\Local\Programs\Python\Python311\Lib\site-packages\httpx\_transports\default.py", line 66, in map_httpcore_exceptions
    yield
  File "C:\Users\F12$\AppData\Local\Programs\Python\Python311\Lib\site-packages\httpx\_transports\default.py", line 366, in handle_async_request
    resp = await self._pool.handle_async_request(req)
           ^^^^^^^^^^^^^^^^^^^^^^^^^^^^^^^^^^^^^^^^^^
  File "C:\Users\F12$\AppData\Local\Programs\Python\Python311\Lib\site-packages\httpcore\_async\connection_pool.py", line 256, in handle_async_request
    raise exc from None
  File "C:\Users\F12$\AppData\Local\Programs\Python\Python311\Lib\site-packages\httpcore\_async\connection_pool.py", line 236, in handle_async_request
    response = await connection.handle_async_request(
               ^^^^^^^^^^^^^^^^^^^^^^^^^^^^^^^^^^^^^^
  File "C:\Users\F12$\AppData\Local\Programs\Python\Python311\Lib\site-packages\httpcore\_async\connection.py", line 101, in handle_async_request
    raise exc
  File "C:\Users\F12$\AppData\Local\Programs\Python\Python311\Lib\site-packages\httpcore\_async\connection.py", line 78, in handle_async_request
    stream = await self._connect(request)
             ^^^^^^^^^^^^^^^^^^^^^^^^^^^^
  File "C:\Users\F12$\AppData\Local\Programs\Python\Python311\Lib\site-packages\httpcore\_async\connection.py", line 124, in _connect
    stream = await self._network_backend.connect_tcp(**kwargs)
             ^^^^^^^^^^^^^^^^^^^^^^^^^^^^^^^^^^^^^^^^^^^^^^^^^
  File "C:\Users\F12$\AppData\Local\Programs\Python\Python311\Lib\site-packages\httpcore\_backends\auto.py", line 31, in connect_tcp
    return await self._backend.connect_tcp(
           ^^^^^^^^^^^^^^^^^^^^^^^^^^^^^^^^
  File "C:\Users\F12$\AppData\Local\Programs\Python\Python311\Lib\site-packages\httpcore\_backends\anyio.py", line 113, in connect_tcp
    with map_exceptions(exc_map):
  File "C:\Users\F12$\AppData\Local\Programs\Python\Python311\Lib\contextlib.py", line 158, in __exit__
    self.gen.throw(typ, value, traceback)
  File "C:\Users\F12$\AppData\Local\Programs\Python\Python311\Lib\site-packages\httpcore\_exceptions.py", line 14, in map_exceptions
    raise to_exc(exc) from exc
httpcore.ConnectError: [Errno 11001] getaddrinfo failed

The above exception was the direct cause of the following exception:

Traceback (most recent call last):
  File "C:\Users\F12$\AppData\Local\Programs\Python\Python311\Lib\site-packages\telegram\request\_httpxrequest.py", line 268, in do_request
    res = await self._client.request(
          ^^^^^^^^^^^^^^^^^^^^^^^^^^^
  File "C:\Users\F12$\AppData\Local\Programs\Python\Python311\Lib\site-packages\httpx\_client.py", line 1530, in request
    return await self.send(request, auth=auth, follow_redirects=follow_redirects)
           ^^^^^^^^^^^^^^^^^^^^^^^^^^^^^^^^^^^^^^^^^^^^^^^^^^^^^^^^^^^^^^^^^^^^^^
  File "C:\Users\F12$\AppData\Local\Programs\Python\Python311\Lib\site-packages\httpx\_client.py", line 1617, in send
    response = await self._send_handling_auth(
               ^^^^^^^^^^^^^^^^^^^^^^^^^^^^^^^
  File "C:\Users\F12$\AppData\Local\Programs\Python\Python311\Lib\site-packages\httpx\_client.py", line 1645, in _send_handling_auth
    response = await self._send_handling_redirects(
               ^^^^^^^^^^^^^^^^^^^^^^^^^^^^^^^^^^^^
  File "C:\Users\F12$\AppData\Local\Programs\Python\Python311\Lib\site-packages\httpx\_client.py", line 1682, in _send_handling_redirects
    response = await self._send_single_request(request)
               ^^^^^^^^^^^^^^^^^^^^^^^^^^^^^^^^^^^^^^^^
  File "C:\Users\F12$\AppData\Local\Programs\Python\Python311\Lib\site-packages\httpx\_client.py", line 1719, in _send_single_request
    response = await transport.handle_async_request(request)
               ^^^^^^^^^^^^^^^^^^^^^^^^^^^^^^^^^^^^^^^^^^^^^
  File "C:\Users\F12$\AppData\Local\Programs\Python\Python311\Lib\site-packages\httpx\_transports\default.py", line 365, in handle_async_request
    with map_httpcore_exceptions():
  File "C:\Users\F12$\AppData\Local\Programs\Python\Python311\Lib\contextlib.py", line 158, in __exit__
    self.gen.throw(typ, value, traceback)
  File "C:\Users\F12$\AppData\Local\Programs\Python\Python311\Lib\site-packages\httpx\_transports\default.py", line 83, in map_httpcore_exceptions
    raise mapped_exc(message) from exc
httpx.ConnectError: [Errno 11001] getaddrinfo failed

The above exception was the direct cause of the following exception:

Traceback (most recent call last):
  File "C:\Users\F12$\AppData\Local\Programs\Python\Python311\Lib\site-packages\telegram\ext\_updater.py", line 688, in _network_loop_retry
    if not await action_cb():
           ^^^^^^^^^^^^^^^^^
  File "C:\Users\F12$\AppData\Local\Programs\Python\Python311\Lib\site-packages\telegram\ext\_updater.py", line 384, in polling_action_cb
    raise exc
  File "C:\Users\F12$\AppData\Local\Programs\Python\Python311\Lib\site-packages\telegram\ext\_updater.py", line 373, in polling_action_cb
    updates = await self.bot.get_updates(
              ^^^^^^^^^^^^^^^^^^^^^^^^^^^
  File "C:\Users\F12$\AppData\Local\Programs\Python\Python311\Lib\site-packages\telegram\ext\_extbot.py", line 558, in get_updates
    updates = await super().get_updates(
              ^^^^^^^^^^^^^^^^^^^^^^^^^^
  File "C:\Users\F12$\AppData\Local\Programs\Python\Python311\Lib\site-packages\telegram\_bot.py", line 525, in decorator
    result = await func(self, *args, **kwargs)  # skipcq: PYL-E1102
             ^^^^^^^^^^^^^^^^^^^^^^^^^^^^^^^^^
  File "C:\Users\F12$\AppData\Local\Programs\Python\Python311\Lib\site-packages\telegram\_bot.py", line 3584, in get_updates
    await self._post(
  File "C:\Users\F12$\AppData\Local\Programs\Python\Python311\Lib\site-packages\telegram\_bot.py", line 613, in _post
    return await self._do_post(
           ^^^^^^^^^^^^^^^^^^^^
  File "C:\Users\F12$\AppData\Local\Programs\Python\Python311\Lib\site-packages\telegram\ext\_extbot.py", line 340, in _do_post
    return await super()._do_post(
           ^^^^^^^^^^^^^^^^^^^^^^^
  File "C:\Users\F12$\AppData\Local\Programs\Python\Python311\Lib\site-packages\telegram\_bot.py", line 641, in _do_post
    return await request.post(
           ^^^^^^^^^^^^^^^^^^^
  File "C:\Users\F12$\AppData\Local\Programs\Python\Python311\Lib\site-packages\telegram\request\_baserequest.py", line 200, in post
    result = await self._request_wrapper(
             ^^^^^^^^^^^^^^^^^^^^^^^^^^^^
  File "C:\Users\F12$\AppData\Local\Programs\Python\Python311\Lib\site-packages\telegram\request\_baserequest.py", line 340, in _request_wrapper
    raise exc
  File "C:\Users\F12$\AppData\Local\Programs\Python\Python311\Lib\site-packages\telegram\request\_baserequest.py", line 330, in _request_wrapper
    code, payload = await self.do_request(
                    ^^^^^^^^^^^^^^^^^^^^^^
  File "C:\Users\F12$\AppData\Local\Programs\Python\Python311\Lib\site-packages\telegram\request\_httpxrequest.py", line 292, in do_request
    raise NetworkError(f"httpx.{err.__class__.__name__}: {err}") from err
telegram.error.NetworkError: httpx.ConnectError: [Errno 11001] getaddrinfo failed
